2025-10-01 23:47:00,880 ERROR scheduler Exception in Enqueue Events for Site erpnext.localhost
Traceback (most recent call last):
  File "/Users/mohammednishamnk/Documents/works/startecht/env/lib/python3.13/site-packages/redis/connection.py", line 385, in connect_check_health
    sock = self.retry.call_with_retry(
        lambda: self._connect(), lambda error: self.disconnect(error)
    )
  File "/Users/mohammednishamnk/Documents/works/startecht/env/lib/python3.13/site-packages/redis/retry.py", line 87, in call_with_retry
    return do()
  File "/Users/mohammednishamnk/Documents/works/startecht/env/lib/python3.13/site-packages/redis/connection.py", line 386, in <lambda>
    lambda: self._connect(), lambda error: self.disconnect(error)
            ~~~~~~~~~~~~~^^
  File "/Users/mohammednishamnk/Documents/works/startecht/env/lib/python3.13/site-packages/redis/connection.py", line 797, in _connect
    raise err
  File "/Users/mohammednishamnk/Documents/works/startecht/env/lib/python3.13/site-packages/redis/connection.py", line 781, in _connect
    sock.connect(socket_address)
    ~~~~~~~~~~~~^^^^^^^^^^^^^^^^
ConnectionRefusedError: [Errno 61] Connection refused

During handling of the above exception, another exception occurred:

Traceback (most recent call last):
  File "/Users/mohammednishamnk/Documents/works/startecht/apps/frappe/frappe/utils/scheduler.py", line 120, in enqueue_events_for_site
    enqueue_events()
    ~~~~~~~~~~~~~~^^
  File "/Users/mohammednishamnk/Documents/works/startecht/apps/frappe/frappe/utils/scheduler.py", line 140, in enqueue_events
    if job_type.enqueue():
       ~~~~~~~~~~~~~~~~^^
  File "/Users/mohammednishamnk/Documents/works/startecht/apps/frappe/frappe/core/doctype/scheduled_job_type/scheduled_job_type.py", line 74, in enqueue
    if not self.is_job_in_queue():
           ~~~~~~~~~~~~~~~~~~~~^^
  File "/Users/mohammednishamnk/Documents/works/startecht/apps/frappe/frappe/core/doctype/scheduled_job_type/scheduled_job_type.py", line 96, in is_job_in_queue
    return is_job_enqueued(self.rq_job_id)
  File "/Users/mohammednishamnk/Documents/works/startecht/apps/frappe/frappe/utils/background_jobs.py", line 665, in is_job_enqueued
    return get_job_status(job_id) in (JobStatus.QUEUED, JobStatus.STARTED)
           ~~~~~~~~~~~~~~^^^^^^^^
  File "/Users/mohammednishamnk/Documents/works/startecht/apps/frappe/frappe/utils/background_jobs.py", line 670, in get_job_status
    if job := get_job(job_id):
              ~~~~~~~^^^^^^^^
  File "/Users/mohammednishamnk/Documents/works/startecht/apps/frappe/frappe/utils/background_jobs.py", line 676, in get_job
    return Job.fetch(create_job_id(job_id), connection=get_redis_conn())
           ~~~~~~~~~^^^^^^^^^^^^^^^^^^^^^^^^^^^^^^^^^^^^^^^^^^^^^^^^^^^^
  File "/Users/mohammednishamnk/Documents/works/startecht/env/lib/python3.13/site-packages/rq/job.py", line 674, in fetch
    job.refresh()
    ~~~~~~~~~~~^^
  File "/Users/mohammednishamnk/Documents/works/startecht/env/lib/python3.13/site-packages/rq/job.py", line 1037, in refresh
    data = self.connection.hgetall(self.key)
  File "/Users/mohammednishamnk/Documents/works/startecht/env/lib/python3.13/site-packages/redis/commands/core.py", line 4959, in hgetall
    return self.execute_command("HGETALL", name, keys=[name])
           ~~~~~~~~~~~~~~~~~~~~^^^^^^^^^^^^^^^^^^^^^^^^^^^^^^
  File "/Users/mohammednishamnk/Documents/works/startecht/env/lib/python3.13/site-packages/redis/client.py", line 623, in execute_command
    return self._execute_command(*args, **options)
           ~~~~~~~~~~~~~~~~~~~~~^^^^^^^^^^^^^^^^^^
  File "/Users/mohammednishamnk/Documents/works/startecht/env/lib/python3.13/site-packages/redis/client.py", line 629, in _execute_command
    conn = self.connection or pool.get_connection()
                              ~~~~~~~~~~~~~~~~~~~^^
  File "/Users/mohammednishamnk/Documents/works/startecht/env/lib/python3.13/site-packages/redis/utils.py", line 191, in wrapper
    return func(*args, **kwargs)
  File "/Users/mohammednishamnk/Documents/works/startecht/env/lib/python3.13/site-packages/redis/connection.py", line 1530, in get_connection
    connection.connect()
    ~~~~~~~~~~~~~~~~~~^^
  File "/Users/mohammednishamnk/Documents/works/startecht/env/lib/python3.13/site-packages/redis/connection.py", line 379, in connect
    self.connect_check_health(check_health=True)
    ~~~~~~~~~~~~~~~~~~~~~~~~~^^^^^^^^^^^^^^^^^^^
  File "/Users/mohammednishamnk/Documents/works/startecht/env/lib/python3.13/site-packages/redis/connection.py", line 391, in connect_check_health
    raise ConnectionError(self._error_message(e))
redis.exceptions.ConnectionError: Error 61 connecting to 127.0.0.1:11000. Connection refused.
2025-10-02 01:48:02,182 ERROR scheduler Exception in Enqueue Events for Site erpnext.localhost
Traceback (most recent call last):
  File "/Users/mohammednishamnk/Documents/works/startecht/env/lib/python3.13/site-packages/redis/connection.py", line 385, in connect_check_health
    sock = self.retry.call_with_retry(
        lambda: self._connect(), lambda error: self.disconnect(error)
    )
  File "/Users/mohammednishamnk/Documents/works/startecht/env/lib/python3.13/site-packages/redis/retry.py", line 87, in call_with_retry
    return do()
  File "/Users/mohammednishamnk/Documents/works/startecht/env/lib/python3.13/site-packages/redis/connection.py", line 386, in <lambda>
    lambda: self._connect(), lambda error: self.disconnect(error)
            ~~~~~~~~~~~~~^^
  File "/Users/mohammednishamnk/Documents/works/startecht/env/lib/python3.13/site-packages/redis/connection.py", line 797, in _connect
    raise err
  File "/Users/mohammednishamnk/Documents/works/startecht/env/lib/python3.13/site-packages/redis/connection.py", line 781, in _connect
    sock.connect(socket_address)
    ~~~~~~~~~~~~^^^^^^^^^^^^^^^^
ConnectionRefusedError: [Errno 61] Connection refused

During handling of the above exception, another exception occurred:

Traceback (most recent call last):
  File "/Users/mohammednishamnk/Documents/works/startecht/apps/frappe/frappe/utils/scheduler.py", line 120, in enqueue_events_for_site
    enqueue_events()
    ~~~~~~~~~~~~~~^^
  File "/Users/mohammednishamnk/Documents/works/startecht/apps/frappe/frappe/utils/scheduler.py", line 140, in enqueue_events
    if job_type.enqueue():
       ~~~~~~~~~~~~~~~~^^
  File "/Users/mohammednishamnk/Documents/works/startecht/apps/frappe/frappe/core/doctype/scheduled_job_type/scheduled_job_type.py", line 74, in enqueue
    if not self.is_job_in_queue():
           ~~~~~~~~~~~~~~~~~~~~^^
  File "/Users/mohammednishamnk/Documents/works/startecht/apps/frappe/frappe/core/doctype/scheduled_job_type/scheduled_job_type.py", line 96, in is_job_in_queue
    return is_job_enqueued(self.rq_job_id)
  File "/Users/mohammednishamnk/Documents/works/startecht/apps/frappe/frappe/utils/background_jobs.py", line 665, in is_job_enqueued
    return get_job_status(job_id) in (JobStatus.QUEUED, JobStatus.STARTED)
           ~~~~~~~~~~~~~~^^^^^^^^
  File "/Users/mohammednishamnk/Documents/works/startecht/apps/frappe/frappe/utils/background_jobs.py", line 670, in get_job_status
    if job := get_job(job_id):
              ~~~~~~~^^^^^^^^
  File "/Users/mohammednishamnk/Documents/works/startecht/apps/frappe/frappe/utils/background_jobs.py", line 676, in get_job
    return Job.fetch(create_job_id(job_id), connection=get_redis_conn())
           ~~~~~~~~~^^^^^^^^^^^^^^^^^^^^^^^^^^^^^^^^^^^^^^^^^^^^^^^^^^^^
  File "/Users/mohammednishamnk/Documents/works/startecht/env/lib/python3.13/site-packages/rq/job.py", line 674, in fetch
    job.refresh()
    ~~~~~~~~~~~^^
  File "/Users/mohammednishamnk/Documents/works/startecht/env/lib/python3.13/site-packages/rq/job.py", line 1037, in refresh
    data = self.connection.hgetall(self.key)
  File "/Users/mohammednishamnk/Documents/works/startecht/env/lib/python3.13/site-packages/redis/commands/core.py", line 4959, in hgetall
    return self.execute_command("HGETALL", name, keys=[name])
           ~~~~~~~~~~~~~~~~~~~~^^^^^^^^^^^^^^^^^^^^^^^^^^^^^^
  File "/Users/mohammednishamnk/Documents/works/startecht/env/lib/python3.13/site-packages/redis/client.py", line 623, in execute_command
    return self._execute_command(*args, **options)
           ~~~~~~~~~~~~~~~~~~~~~^^^^^^^^^^^^^^^^^^
  File "/Users/mohammednishamnk/Documents/works/startecht/env/lib/python3.13/site-packages/redis/client.py", line 629, in _execute_command
    conn = self.connection or pool.get_connection()
                              ~~~~~~~~~~~~~~~~~~~^^
  File "/Users/mohammednishamnk/Documents/works/startecht/env/lib/python3.13/site-packages/redis/utils.py", line 191, in wrapper
    return func(*args, **kwargs)
  File "/Users/mohammednishamnk/Documents/works/startecht/env/lib/python3.13/site-packages/redis/connection.py", line 1530, in get_connection
    connection.connect()
    ~~~~~~~~~~~~~~~~~~^^
  File "/Users/mohammednishamnk/Documents/works/startecht/env/lib/python3.13/site-packages/redis/connection.py", line 379, in connect
    self.connect_check_health(check_health=True)
    ~~~~~~~~~~~~~~~~~~~~~~~~~^^^^^^^^^^^^^^^^^^^
  File "/Users/mohammednishamnk/Documents/works/startecht/env/lib/python3.13/site-packages/redis/connection.py", line 391, in connect_check_health
    raise ConnectionError(self._error_message(e))
redis.exceptions.ConnectionError: Error 61 connecting to 127.0.0.1:11000. Connection refused.
2025-10-02 02:49:21,956 ERROR scheduler Exception in Enqueue Events for Site erpnext.localhost
Traceback (most recent call last):
  File "/Users/mohammednishamnk/Documents/works/startecht/env/lib/python3.13/site-packages/redis/connection.py", line 385, in connect_check_health
    sock = self.retry.call_with_retry(
        lambda: self._connect(), lambda error: self.disconnect(error)
    )
  File "/Users/mohammednishamnk/Documents/works/startecht/env/lib/python3.13/site-packages/redis/retry.py", line 87, in call_with_retry
    return do()
  File "/Users/mohammednishamnk/Documents/works/startecht/env/lib/python3.13/site-packages/redis/connection.py", line 386, in <lambda>
    lambda: self._connect(), lambda error: self.disconnect(error)
            ~~~~~~~~~~~~~^^
  File "/Users/mohammednishamnk/Documents/works/startecht/env/lib/python3.13/site-packages/redis/connection.py", line 797, in _connect
    raise err
  File "/Users/mohammednishamnk/Documents/works/startecht/env/lib/python3.13/site-packages/redis/connection.py", line 781, in _connect
    sock.connect(socket_address)
    ~~~~~~~~~~~~^^^^^^^^^^^^^^^^
ConnectionRefusedError: [Errno 61] Connection refused

During handling of the above exception, another exception occurred:

Traceback (most recent call last):
  File "/Users/mohammednishamnk/Documents/works/startecht/apps/frappe/frappe/utils/scheduler.py", line 120, in enqueue_events_for_site
    enqueue_events()
    ~~~~~~~~~~~~~~^^
  File "/Users/mohammednishamnk/Documents/works/startecht/apps/frappe/frappe/utils/scheduler.py", line 140, in enqueue_events
    if job_type.enqueue():
       ~~~~~~~~~~~~~~~~^^
  File "/Users/mohammednishamnk/Documents/works/startecht/apps/frappe/frappe/core/doctype/scheduled_job_type/scheduled_job_type.py", line 74, in enqueue
    if not self.is_job_in_queue():
           ~~~~~~~~~~~~~~~~~~~~^^
  File "/Users/mohammednishamnk/Documents/works/startecht/apps/frappe/frappe/core/doctype/scheduled_job_type/scheduled_job_type.py", line 96, in is_job_in_queue
    return is_job_enqueued(self.rq_job_id)
  File "/Users/mohammednishamnk/Documents/works/startecht/apps/frappe/frappe/utils/background_jobs.py", line 665, in is_job_enqueued
    return get_job_status(job_id) in (JobStatus.QUEUED, JobStatus.STARTED)
           ~~~~~~~~~~~~~~^^^^^^^^
  File "/Users/mohammednishamnk/Documents/works/startecht/apps/frappe/frappe/utils/background_jobs.py", line 670, in get_job_status
    if job := get_job(job_id):
              ~~~~~~~^^^^^^^^
  File "/Users/mohammednishamnk/Documents/works/startecht/apps/frappe/frappe/utils/background_jobs.py", line 676, in get_job
    return Job.fetch(create_job_id(job_id), connection=get_redis_conn())
           ~~~~~~~~~^^^^^^^^^^^^^^^^^^^^^^^^^^^^^^^^^^^^^^^^^^^^^^^^^^^^
  File "/Users/mohammednishamnk/Documents/works/startecht/env/lib/python3.13/site-packages/rq/job.py", line 674, in fetch
    job.refresh()
    ~~~~~~~~~~~^^
  File "/Users/mohammednishamnk/Documents/works/startecht/env/lib/python3.13/site-packages/rq/job.py", line 1037, in refresh
    data = self.connection.hgetall(self.key)
  File "/Users/mohammednishamnk/Documents/works/startecht/env/lib/python3.13/site-packages/redis/commands/core.py", line 4959, in hgetall
    return self.execute_command("HGETALL", name, keys=[name])
           ~~~~~~~~~~~~~~~~~~~~^^^^^^^^^^^^^^^^^^^^^^^^^^^^^^
  File "/Users/mohammednishamnk/Documents/works/startecht/env/lib/python3.13/site-packages/redis/client.py", line 623, in execute_command
    return self._execute_command(*args, **options)
           ~~~~~~~~~~~~~~~~~~~~~^^^^^^^^^^^^^^^^^^
  File "/Users/mohammednishamnk/Documents/works/startecht/env/lib/python3.13/site-packages/redis/client.py", line 629, in _execute_command
    conn = self.connection or pool.get_connection()
                              ~~~~~~~~~~~~~~~~~~~^^
  File "/Users/mohammednishamnk/Documents/works/startecht/env/lib/python3.13/site-packages/redis/utils.py", line 191, in wrapper
    return func(*args, **kwargs)
  File "/Users/mohammednishamnk/Documents/works/startecht/env/lib/python3.13/site-packages/redis/connection.py", line 1530, in get_connection
    connection.connect()
    ~~~~~~~~~~~~~~~~~~^^
  File "/Users/mohammednishamnk/Documents/works/startecht/env/lib/python3.13/site-packages/redis/connection.py", line 379, in connect
    self.connect_check_health(check_health=True)
    ~~~~~~~~~~~~~~~~~~~~~~~~~^^^^^^^^^^^^^^^^^^^
  File "/Users/mohammednishamnk/Documents/works/startecht/env/lib/python3.13/site-packages/redis/connection.py", line 391, in connect_check_health
    raise ConnectionError(self._error_message(e))
redis.exceptions.ConnectionError: Error 61 connecting to 127.0.0.1:11000. Connection refused.
2025-10-02 03:04:07,074 ERROR scheduler Exception in Enqueue Events for Site erpnext.localhost
Traceback (most recent call last):
  File "/Users/mohammednishamnk/Documents/works/startecht/env/lib/python3.13/site-packages/redis/connection.py", line 385, in connect_check_health
    sock = self.retry.call_with_retry(
        lambda: self._connect(), lambda error: self.disconnect(error)
    )
  File "/Users/mohammednishamnk/Documents/works/startecht/env/lib/python3.13/site-packages/redis/retry.py", line 87, in call_with_retry
    return do()
  File "/Users/mohammednishamnk/Documents/works/startecht/env/lib/python3.13/site-packages/redis/connection.py", line 386, in <lambda>
    lambda: self._connect(), lambda error: self.disconnect(error)
            ~~~~~~~~~~~~~^^
  File "/Users/mohammednishamnk/Documents/works/startecht/env/lib/python3.13/site-packages/redis/connection.py", line 797, in _connect
    raise err
  File "/Users/mohammednishamnk/Documents/works/startecht/env/lib/python3.13/site-packages/redis/connection.py", line 781, in _connect
    sock.connect(socket_address)
    ~~~~~~~~~~~~^^^^^^^^^^^^^^^^
ConnectionRefusedError: [Errno 61] Connection refused

During handling of the above exception, another exception occurred:

Traceback (most recent call last):
  File "/Users/mohammednishamnk/Documents/works/startecht/apps/frappe/frappe/utils/scheduler.py", line 120, in enqueue_events_for_site
    enqueue_events()
    ~~~~~~~~~~~~~~^^
  File "/Users/mohammednishamnk/Documents/works/startecht/apps/frappe/frappe/utils/scheduler.py", line 140, in enqueue_events
    if job_type.enqueue():
       ~~~~~~~~~~~~~~~~^^
  File "/Users/mohammednishamnk/Documents/works/startecht/apps/frappe/frappe/core/doctype/scheduled_job_type/scheduled_job_type.py", line 74, in enqueue
    if not self.is_job_in_queue():
           ~~~~~~~~~~~~~~~~~~~~^^
  File "/Users/mohammednishamnk/Documents/works/startecht/apps/frappe/frappe/core/doctype/scheduled_job_type/scheduled_job_type.py", line 96, in is_job_in_queue
    return is_job_enqueued(self.rq_job_id)
  File "/Users/mohammednishamnk/Documents/works/startecht/apps/frappe/frappe/utils/background_jobs.py", line 665, in is_job_enqueued
    return get_job_status(job_id) in (JobStatus.QUEUED, JobStatus.STARTED)
           ~~~~~~~~~~~~~~^^^^^^^^
  File "/Users/mohammednishamnk/Documents/works/startecht/apps/frappe/frappe/utils/background_jobs.py", line 670, in get_job_status
    if job := get_job(job_id):
              ~~~~~~~^^^^^^^^
  File "/Users/mohammednishamnk/Documents/works/startecht/apps/frappe/frappe/utils/background_jobs.py", line 676, in get_job
    return Job.fetch(create_job_id(job_id), connection=get_redis_conn())
           ~~~~~~~~~^^^^^^^^^^^^^^^^^^^^^^^^^^^^^^^^^^^^^^^^^^^^^^^^^^^^
  File "/Users/mohammednishamnk/Documents/works/startecht/env/lib/python3.13/site-packages/rq/job.py", line 674, in fetch
    job.refresh()
    ~~~~~~~~~~~^^
  File "/Users/mohammednishamnk/Documents/works/startecht/env/lib/python3.13/site-packages/rq/job.py", line 1037, in refresh
    data = self.connection.hgetall(self.key)
  File "/Users/mohammednishamnk/Documents/works/startecht/env/lib/python3.13/site-packages/redis/commands/core.py", line 4959, in hgetall
    return self.execute_command("HGETALL", name, keys=[name])
           ~~~~~~~~~~~~~~~~~~~~^^^^^^^^^^^^^^^^^^^^^^^^^^^^^^
  File "/Users/mohammednishamnk/Documents/works/startecht/env/lib/python3.13/site-packages/redis/client.py", line 623, in execute_command
    return self._execute_command(*args, **options)
           ~~~~~~~~~~~~~~~~~~~~~^^^^^^^^^^^^^^^^^^
  File "/Users/mohammednishamnk/Documents/works/startecht/env/lib/python3.13/site-packages/redis/client.py", line 629, in _execute_command
    conn = self.connection or pool.get_connection()
                              ~~~~~~~~~~~~~~~~~~~^^
  File "/Users/mohammednishamnk/Documents/works/startecht/env/lib/python3.13/site-packages/redis/utils.py", line 191, in wrapper
    return func(*args, **kwargs)
  File "/Users/mohammednishamnk/Documents/works/startecht/env/lib/python3.13/site-packages/redis/connection.py", line 1530, in get_connection
    connection.connect()
    ~~~~~~~~~~~~~~~~~~^^
  File "/Users/mohammednishamnk/Documents/works/startecht/env/lib/python3.13/site-packages/redis/connection.py", line 379, in connect
    self.connect_check_health(check_health=True)
    ~~~~~~~~~~~~~~~~~~~~~~~~~^^^^^^^^^^^^^^^^^^^
  File "/Users/mohammednishamnk/Documents/works/startecht/env/lib/python3.13/site-packages/redis/connection.py", line 391, in connect_check_health
    raise ConnectionError(self._error_message(e))
redis.exceptions.ConnectionError: Error 61 connecting to 127.0.0.1:11000. Connection refused.
2025-10-02 04:05:14,641 ERROR scheduler Exception in Enqueue Events for Site erpnext.localhost
Traceback (most recent call last):
  File "/Users/mohammednishamnk/Documents/works/startecht/env/lib/python3.13/site-packages/redis/connection.py", line 385, in connect_check_health
    sock = self.retry.call_with_retry(
        lambda: self._connect(), lambda error: self.disconnect(error)
    )
  File "/Users/mohammednishamnk/Documents/works/startecht/env/lib/python3.13/site-packages/redis/retry.py", line 87, in call_with_retry
    return do()
  File "/Users/mohammednishamnk/Documents/works/startecht/env/lib/python3.13/site-packages/redis/connection.py", line 386, in <lambda>
    lambda: self._connect(), lambda error: self.disconnect(error)
            ~~~~~~~~~~~~~^^
  File "/Users/mohammednishamnk/Documents/works/startecht/env/lib/python3.13/site-packages/redis/connection.py", line 797, in _connect
    raise err
  File "/Users/mohammednishamnk/Documents/works/startecht/env/lib/python3.13/site-packages/redis/connection.py", line 781, in _connect
    sock.connect(socket_address)
    ~~~~~~~~~~~~^^^^^^^^^^^^^^^^
ConnectionRefusedError: [Errno 61] Connection refused

During handling of the above exception, another exception occurred:

Traceback (most recent call last):
  File "/Users/mohammednishamnk/Documents/works/startecht/apps/frappe/frappe/utils/scheduler.py", line 120, in enqueue_events_for_site
    enqueue_events()
    ~~~~~~~~~~~~~~^^
  File "/Users/mohammednishamnk/Documents/works/startecht/apps/frappe/frappe/utils/scheduler.py", line 140, in enqueue_events
    if job_type.enqueue():
       ~~~~~~~~~~~~~~~~^^
  File "/Users/mohammednishamnk/Documents/works/startecht/apps/frappe/frappe/core/doctype/scheduled_job_type/scheduled_job_type.py", line 74, in enqueue
    if not self.is_job_in_queue():
           ~~~~~~~~~~~~~~~~~~~~^^
  File "/Users/mohammednishamnk/Documents/works/startecht/apps/frappe/frappe/core/doctype/scheduled_job_type/scheduled_job_type.py", line 96, in is_job_in_queue
    return is_job_enqueued(self.rq_job_id)
  File "/Users/mohammednishamnk/Documents/works/startecht/apps/frappe/frappe/utils/background_jobs.py", line 665, in is_job_enqueued
    return get_job_status(job_id) in (JobStatus.QUEUED, JobStatus.STARTED)
           ~~~~~~~~~~~~~~^^^^^^^^
  File "/Users/mohammednishamnk/Documents/works/startecht/apps/frappe/frappe/utils/background_jobs.py", line 670, in get_job_status
    if job := get_job(job_id):
              ~~~~~~~^^^^^^^^
  File "/Users/mohammednishamnk/Documents/works/startecht/apps/frappe/frappe/utils/background_jobs.py", line 676, in get_job
    return Job.fetch(create_job_id(job_id), connection=get_redis_conn())
           ~~~~~~~~~^^^^^^^^^^^^^^^^^^^^^^^^^^^^^^^^^^^^^^^^^^^^^^^^^^^^
  File "/Users/mohammednishamnk/Documents/works/startecht/env/lib/python3.13/site-packages/rq/job.py", line 674, in fetch
    job.refresh()
    ~~~~~~~~~~~^^
  File "/Users/mohammednishamnk/Documents/works/startecht/env/lib/python3.13/site-packages/rq/job.py", line 1037, in refresh
    data = self.connection.hgetall(self.key)
  File "/Users/mohammednishamnk/Documents/works/startecht/env/lib/python3.13/site-packages/redis/commands/core.py", line 4959, in hgetall
    return self.execute_command("HGETALL", name, keys=[name])
           ~~~~~~~~~~~~~~~~~~~~^^^^^^^^^^^^^^^^^^^^^^^^^^^^^^
  File "/Users/mohammednishamnk/Documents/works/startecht/env/lib/python3.13/site-packages/redis/client.py", line 623, in execute_command
    return self._execute_command(*args, **options)
           ~~~~~~~~~~~~~~~~~~~~~^^^^^^^^^^^^^^^^^^
  File "/Users/mohammednishamnk/Documents/works/startecht/env/lib/python3.13/site-packages/redis/client.py", line 629, in _execute_command
    conn = self.connection or pool.get_connection()
                              ~~~~~~~~~~~~~~~~~~~^^
  File "/Users/mohammednishamnk/Documents/works/startecht/env/lib/python3.13/site-packages/redis/utils.py", line 191, in wrapper
    return func(*args, **kwargs)
  File "/Users/mohammednishamnk/Documents/works/startecht/env/lib/python3.13/site-packages/redis/connection.py", line 1530, in get_connection
    connection.connect()
    ~~~~~~~~~~~~~~~~~~^^
  File "/Users/mohammednishamnk/Documents/works/startecht/env/lib/python3.13/site-packages/redis/connection.py", line 379, in connect
    self.connect_check_health(check_health=True)
    ~~~~~~~~~~~~~~~~~~~~~~~~~^^^^^^^^^^^^^^^^^^^
  File "/Users/mohammednishamnk/Documents/works/startecht/env/lib/python3.13/site-packages/redis/connection.py", line 391, in connect_check_health
    raise ConnectionError(self._error_message(e))
redis.exceptions.ConnectionError: Error 61 connecting to 127.0.0.1:11000. Connection refused.
2025-10-02 04:36:02,271 ERROR scheduler Exception in Enqueue Events for Site erpnext.localhost
Traceback (most recent call last):
  File "/Users/mohammednishamnk/Documents/works/startecht/env/lib/python3.13/site-packages/redis/connection.py", line 385, in connect_check_health
    sock = self.retry.call_with_retry(
        lambda: self._connect(), lambda error: self.disconnect(error)
    )
  File "/Users/mohammednishamnk/Documents/works/startecht/env/lib/python3.13/site-packages/redis/retry.py", line 87, in call_with_retry
    return do()
  File "/Users/mohammednishamnk/Documents/works/startecht/env/lib/python3.13/site-packages/redis/connection.py", line 386, in <lambda>
    lambda: self._connect(), lambda error: self.disconnect(error)
            ~~~~~~~~~~~~~^^
  File "/Users/mohammednishamnk/Documents/works/startecht/env/lib/python3.13/site-packages/redis/connection.py", line 797, in _connect
    raise err
  File "/Users/mohammednishamnk/Documents/works/startecht/env/lib/python3.13/site-packages/redis/connection.py", line 781, in _connect
    sock.connect(socket_address)
    ~~~~~~~~~~~~^^^^^^^^^^^^^^^^
ConnectionRefusedError: [Errno 61] Connection refused

During handling of the above exception, another exception occurred:

Traceback (most recent call last):
  File "/Users/mohammednishamnk/Documents/works/startecht/apps/frappe/frappe/utils/scheduler.py", line 120, in enqueue_events_for_site
    enqueue_events()
    ~~~~~~~~~~~~~~^^
  File "/Users/mohammednishamnk/Documents/works/startecht/apps/frappe/frappe/utils/scheduler.py", line 140, in enqueue_events
    if job_type.enqueue():
       ~~~~~~~~~~~~~~~~^^
  File "/Users/mohammednishamnk/Documents/works/startecht/apps/frappe/frappe/core/doctype/scheduled_job_type/scheduled_job_type.py", line 74, in enqueue
    if not self.is_job_in_queue():
           ~~~~~~~~~~~~~~~~~~~~^^
  File "/Users/mohammednishamnk/Documents/works/startecht/apps/frappe/frappe/core/doctype/scheduled_job_type/scheduled_job_type.py", line 96, in is_job_in_queue
    return is_job_enqueued(self.rq_job_id)
  File "/Users/mohammednishamnk/Documents/works/startecht/apps/frappe/frappe/utils/background_jobs.py", line 665, in is_job_enqueued
    return get_job_status(job_id) in (JobStatus.QUEUED, JobStatus.STARTED)
           ~~~~~~~~~~~~~~^^^^^^^^
  File "/Users/mohammednishamnk/Documents/works/startecht/apps/frappe/frappe/utils/background_jobs.py", line 670, in get_job_status
    if job := get_job(job_id):
              ~~~~~~~^^^^^^^^
  File "/Users/mohammednishamnk/Documents/works/startecht/apps/frappe/frappe/utils/background_jobs.py", line 676, in get_job
    return Job.fetch(create_job_id(job_id), connection=get_redis_conn())
           ~~~~~~~~~^^^^^^^^^^^^^^^^^^^^^^^^^^^^^^^^^^^^^^^^^^^^^^^^^^^^
  File "/Users/mohammednishamnk/Documents/works/startecht/env/lib/python3.13/site-packages/rq/job.py", line 674, in fetch
    job.refresh()
    ~~~~~~~~~~~^^
  File "/Users/mohammednishamnk/Documents/works/startecht/env/lib/python3.13/site-packages/rq/job.py", line 1037, in refresh
    data = self.connection.hgetall(self.key)
  File "/Users/mohammednishamnk/Documents/works/startecht/env/lib/python3.13/site-packages/redis/commands/core.py", line 4959, in hgetall
    return self.execute_command("HGETALL", name, keys=[name])
           ~~~~~~~~~~~~~~~~~~~~^^^^^^^^^^^^^^^^^^^^^^^^^^^^^^
  File "/Users/mohammednishamnk/Documents/works/startecht/env/lib/python3.13/site-packages/redis/client.py", line 623, in execute_command
    return self._execute_command(*args, **options)
           ~~~~~~~~~~~~~~~~~~~~~^^^^^^^^^^^^^^^^^^
  File "/Users/mohammednishamnk/Documents/works/startecht/env/lib/python3.13/site-packages/redis/client.py", line 629, in _execute_command
    conn = self.connection or pool.get_connection()
                              ~~~~~~~~~~~~~~~~~~~^^
  File "/Users/mohammednishamnk/Documents/works/startecht/env/lib/python3.13/site-packages/redis/utils.py", line 191, in wrapper
    return func(*args, **kwargs)
  File "/Users/mohammednishamnk/Documents/works/startecht/env/lib/python3.13/site-packages/redis/connection.py", line 1530, in get_connection
    connection.connect()
    ~~~~~~~~~~~~~~~~~~^^
  File "/Users/mohammednishamnk/Documents/works/startecht/env/lib/python3.13/site-packages/redis/connection.py", line 379, in connect
    self.connect_check_health(check_health=True)
    ~~~~~~~~~~~~~~~~~~~~~~~~~^^^^^^^^^^^^^^^^^^^
  File "/Users/mohammednishamnk/Documents/works/startecht/env/lib/python3.13/site-packages/redis/connection.py", line 391, in connect_check_health
    raise ConnectionError(self._error_message(e))
redis.exceptions.ConnectionError: Error 61 connecting to 127.0.0.1:11000. Connection refused.
2025-10-02 05:37:08,537 ERROR scheduler Exception in Enqueue Events for Site erpnext.localhost
Traceback (most recent call last):
  File "/Users/mohammednishamnk/Documents/works/startecht/env/lib/python3.13/site-packages/redis/connection.py", line 385, in connect_check_health
    sock = self.retry.call_with_retry(
        lambda: self._connect(), lambda error: self.disconnect(error)
    )
  File "/Users/mohammednishamnk/Documents/works/startecht/env/lib/python3.13/site-packages/redis/retry.py", line 87, in call_with_retry
    return do()
  File "/Users/mohammednishamnk/Documents/works/startecht/env/lib/python3.13/site-packages/redis/connection.py", line 386, in <lambda>
    lambda: self._connect(), lambda error: self.disconnect(error)
            ~~~~~~~~~~~~~^^
  File "/Users/mohammednishamnk/Documents/works/startecht/env/lib/python3.13/site-packages/redis/connection.py", line 797, in _connect
    raise err
  File "/Users/mohammednishamnk/Documents/works/startecht/env/lib/python3.13/site-packages/redis/connection.py", line 781, in _connect
    sock.connect(socket_address)
    ~~~~~~~~~~~~^^^^^^^^^^^^^^^^
ConnectionRefusedError: [Errno 61] Connection refused

During handling of the above exception, another exception occurred:

Traceback (most recent call last):
  File "/Users/mohammednishamnk/Documents/works/startecht/apps/frappe/frappe/utils/scheduler.py", line 120, in enqueue_events_for_site
    enqueue_events()
    ~~~~~~~~~~~~~~^^
  File "/Users/mohammednishamnk/Documents/works/startecht/apps/frappe/frappe/utils/scheduler.py", line 140, in enqueue_events
    if job_type.enqueue():
       ~~~~~~~~~~~~~~~~^^
  File "/Users/mohammednishamnk/Documents/works/startecht/apps/frappe/frappe/core/doctype/scheduled_job_type/scheduled_job_type.py", line 74, in enqueue
    if not self.is_job_in_queue():
           ~~~~~~~~~~~~~~~~~~~~^^
  File "/Users/mohammednishamnk/Documents/works/startecht/apps/frappe/frappe/core/doctype/scheduled_job_type/scheduled_job_type.py", line 96, in is_job_in_queue
    return is_job_enqueued(self.rq_job_id)
  File "/Users/mohammednishamnk/Documents/works/startecht/apps/frappe/frappe/utils/background_jobs.py", line 665, in is_job_enqueued
    return get_job_status(job_id) in (JobStatus.QUEUED, JobStatus.STARTED)
           ~~~~~~~~~~~~~~^^^^^^^^
  File "/Users/mohammednishamnk/Documents/works/startecht/apps/frappe/frappe/utils/background_jobs.py", line 670, in get_job_status
    if job := get_job(job_id):
              ~~~~~~~^^^^^^^^
  File "/Users/mohammednishamnk/Documents/works/startecht/apps/frappe/frappe/utils/background_jobs.py", line 676, in get_job
    return Job.fetch(create_job_id(job_id), connection=get_redis_conn())
           ~~~~~~~~~^^^^^^^^^^^^^^^^^^^^^^^^^^^^^^^^^^^^^^^^^^^^^^^^^^^^
  File "/Users/mohammednishamnk/Documents/works/startecht/env/lib/python3.13/site-packages/rq/job.py", line 674, in fetch
    job.refresh()
    ~~~~~~~~~~~^^
  File "/Users/mohammednishamnk/Documents/works/startecht/env/lib/python3.13/site-packages/rq/job.py", line 1037, in refresh
    data = self.connection.hgetall(self.key)
  File "/Users/mohammednishamnk/Documents/works/startecht/env/lib/python3.13/site-packages/redis/commands/core.py", line 4959, in hgetall
    return self.execute_command("HGETALL", name, keys=[name])
           ~~~~~~~~~~~~~~~~~~~~^^^^^^^^^^^^^^^^^^^^^^^^^^^^^^
  File "/Users/mohammednishamnk/Documents/works/startecht/env/lib/python3.13/site-packages/redis/client.py", line 623, in execute_command
    return self._execute_command(*args, **options)
           ~~~~~~~~~~~~~~~~~~~~~^^^^^^^^^^^^^^^^^^
  File "/Users/mohammednishamnk/Documents/works/startecht/env/lib/python3.13/site-packages/redis/client.py", line 629, in _execute_command
    conn = self.connection or pool.get_connection()
                              ~~~~~~~~~~~~~~~~~~~^^
  File "/Users/mohammednishamnk/Documents/works/startecht/env/lib/python3.13/site-packages/redis/utils.py", line 191, in wrapper
    return func(*args, **kwargs)
  File "/Users/mohammednishamnk/Documents/works/startecht/env/lib/python3.13/site-packages/redis/connection.py", line 1530, in get_connection
    connection.connect()
    ~~~~~~~~~~~~~~~~~~^^
  File "/Users/mohammednishamnk/Documents/works/startecht/env/lib/python3.13/site-packages/redis/connection.py", line 379, in connect
    self.connect_check_health(check_health=True)
    ~~~~~~~~~~~~~~~~~~~~~~~~~^^^^^^^^^^^^^^^^^^^
  File "/Users/mohammednishamnk/Documents/works/startecht/env/lib/python3.13/site-packages/redis/connection.py", line 391, in connect_check_health
    raise ConnectionError(self._error_message(e))
redis.exceptions.ConnectionError: Error 61 connecting to 127.0.0.1:11000. Connection refused.
2025-10-02 06:22:06,564 ERROR scheduler Exception in Enqueue Events for Site erpnext.localhost
Traceback (most recent call last):
  File "/Users/mohammednishamnk/Documents/works/startecht/env/lib/python3.13/site-packages/redis/connection.py", line 385, in connect_check_health
    sock = self.retry.call_with_retry(
        lambda: self._connect(), lambda error: self.disconnect(error)
    )
  File "/Users/mohammednishamnk/Documents/works/startecht/env/lib/python3.13/site-packages/redis/retry.py", line 87, in call_with_retry
    return do()
  File "/Users/mohammednishamnk/Documents/works/startecht/env/lib/python3.13/site-packages/redis/connection.py", line 386, in <lambda>
    lambda: self._connect(), lambda error: self.disconnect(error)
            ~~~~~~~~~~~~~^^
  File "/Users/mohammednishamnk/Documents/works/startecht/env/lib/python3.13/site-packages/redis/connection.py", line 797, in _connect
    raise err
  File "/Users/mohammednishamnk/Documents/works/startecht/env/lib/python3.13/site-packages/redis/connection.py", line 781, in _connect
    sock.connect(socket_address)
    ~~~~~~~~~~~~^^^^^^^^^^^^^^^^
ConnectionRefusedError: [Errno 61] Connection refused

During handling of the above exception, another exception occurred:

Traceback (most recent call last):
  File "/Users/mohammednishamnk/Documents/works/startecht/apps/frappe/frappe/utils/scheduler.py", line 120, in enqueue_events_for_site
    enqueue_events()
    ~~~~~~~~~~~~~~^^
  File "/Users/mohammednishamnk/Documents/works/startecht/apps/frappe/frappe/utils/scheduler.py", line 140, in enqueue_events
    if job_type.enqueue():
       ~~~~~~~~~~~~~~~~^^
  File "/Users/mohammednishamnk/Documents/works/startecht/apps/frappe/frappe/core/doctype/scheduled_job_type/scheduled_job_type.py", line 74, in enqueue
    if not self.is_job_in_queue():
           ~~~~~~~~~~~~~~~~~~~~^^
  File "/Users/mohammednishamnk/Documents/works/startecht/apps/frappe/frappe/core/doctype/scheduled_job_type/scheduled_job_type.py", line 96, in is_job_in_queue
    return is_job_enqueued(self.rq_job_id)
  File "/Users/mohammednishamnk/Documents/works/startecht/apps/frappe/frappe/utils/background_jobs.py", line 665, in is_job_enqueued
    return get_job_status(job_id) in (JobStatus.QUEUED, JobStatus.STARTED)
           ~~~~~~~~~~~~~~^^^^^^^^
  File "/Users/mohammednishamnk/Documents/works/startecht/apps/frappe/frappe/utils/background_jobs.py", line 670, in get_job_status
    if job := get_job(job_id):
              ~~~~~~~^^^^^^^^
  File "/Users/mohammednishamnk/Documents/works/startecht/apps/frappe/frappe/utils/background_jobs.py", line 676, in get_job
    return Job.fetch(create_job_id(job_id), connection=get_redis_conn())
           ~~~~~~~~~^^^^^^^^^^^^^^^^^^^^^^^^^^^^^^^^^^^^^^^^^^^^^^^^^^^^
  File "/Users/mohammednishamnk/Documents/works/startecht/env/lib/python3.13/site-packages/rq/job.py", line 674, in fetch
    job.refresh()
    ~~~~~~~~~~~^^
  File "/Users/mohammednishamnk/Documents/works/startecht/env/lib/python3.13/site-packages/rq/job.py", line 1037, in refresh
    data = self.connection.hgetall(self.key)
  File "/Users/mohammednishamnk/Documents/works/startecht/env/lib/python3.13/site-packages/redis/commands/core.py", line 4959, in hgetall
    return self.execute_command("HGETALL", name, keys=[name])
           ~~~~~~~~~~~~~~~~~~~~^^^^^^^^^^^^^^^^^^^^^^^^^^^^^^
  File "/Users/mohammednishamnk/Documents/works/startecht/env/lib/python3.13/site-packages/redis/client.py", line 623, in execute_command
    return self._execute_command(*args, **options)
           ~~~~~~~~~~~~~~~~~~~~~^^^^^^^^^^^^^^^^^^
  File "/Users/mohammednishamnk/Documents/works/startecht/env/lib/python3.13/site-packages/redis/client.py", line 629, in _execute_command
    conn = self.connection or pool.get_connection()
                              ~~~~~~~~~~~~~~~~~~~^^
  File "/Users/mohammednishamnk/Documents/works/startecht/env/lib/python3.13/site-packages/redis/utils.py", line 191, in wrapper
    return func(*args, **kwargs)
  File "/Users/mohammednishamnk/Documents/works/startecht/env/lib/python3.13/site-packages/redis/connection.py", line 1530, in get_connection
    connection.connect()
    ~~~~~~~~~~~~~~~~~~^^
  File "/Users/mohammednishamnk/Documents/works/startecht/env/lib/python3.13/site-packages/redis/connection.py", line 379, in connect
    self.connect_check_health(check_health=True)
    ~~~~~~~~~~~~~~~~~~~~~~~~~^^^^^^^^^^^^^^^^^^^
  File "/Users/mohammednishamnk/Documents/works/startecht/env/lib/python3.13/site-packages/redis/connection.py", line 391, in connect_check_health
    raise ConnectionError(self._error_message(e))
redis.exceptions.ConnectionError: Error 61 connecting to 127.0.0.1:11000. Connection refused.
2025-10-02 06:26:00,839 ERROR scheduler Exception in Enqueue Events for Site erpnext.localhost
Traceback (most recent call last):
  File "/Users/mohammednishamnk/Documents/works/startecht/env/lib/python3.13/site-packages/redis/connection.py", line 385, in connect_check_health
    sock = self.retry.call_with_retry(
        lambda: self._connect(), lambda error: self.disconnect(error)
    )
  File "/Users/mohammednishamnk/Documents/works/startecht/env/lib/python3.13/site-packages/redis/retry.py", line 87, in call_with_retry
    return do()
  File "/Users/mohammednishamnk/Documents/works/startecht/env/lib/python3.13/site-packages/redis/connection.py", line 386, in <lambda>
    lambda: self._connect(), lambda error: self.disconnect(error)
            ~~~~~~~~~~~~~^^
  File "/Users/mohammednishamnk/Documents/works/startecht/env/lib/python3.13/site-packages/redis/connection.py", line 797, in _connect
    raise err
  File "/Users/mohammednishamnk/Documents/works/startecht/env/lib/python3.13/site-packages/redis/connection.py", line 781, in _connect
    sock.connect(socket_address)
    ~~~~~~~~~~~~^^^^^^^^^^^^^^^^
ConnectionRefusedError: [Errno 61] Connection refused

During handling of the above exception, another exception occurred:

Traceback (most recent call last):
  File "/Users/mohammednishamnk/Documents/works/startecht/apps/frappe/frappe/utils/scheduler.py", line 120, in enqueue_events_for_site
    enqueue_events()
    ~~~~~~~~~~~~~~^^
  File "/Users/mohammednishamnk/Documents/works/startecht/apps/frappe/frappe/utils/scheduler.py", line 140, in enqueue_events
    if job_type.enqueue():
       ~~~~~~~~~~~~~~~~^^
  File "/Users/mohammednishamnk/Documents/works/startecht/apps/frappe/frappe/core/doctype/scheduled_job_type/scheduled_job_type.py", line 74, in enqueue
    if not self.is_job_in_queue():
           ~~~~~~~~~~~~~~~~~~~~^^
  File "/Users/mohammednishamnk/Documents/works/startecht/apps/frappe/frappe/core/doctype/scheduled_job_type/scheduled_job_type.py", line 96, in is_job_in_queue
    return is_job_enqueued(self.rq_job_id)
  File "/Users/mohammednishamnk/Documents/works/startecht/apps/frappe/frappe/utils/background_jobs.py", line 665, in is_job_enqueued
    return get_job_status(job_id) in (JobStatus.QUEUED, JobStatus.STARTED)
           ~~~~~~~~~~~~~~^^^^^^^^
  File "/Users/mohammednishamnk/Documents/works/startecht/apps/frappe/frappe/utils/background_jobs.py", line 670, in get_job_status
    if job := get_job(job_id):
              ~~~~~~~^^^^^^^^
  File "/Users/mohammednishamnk/Documents/works/startecht/apps/frappe/frappe/utils/background_jobs.py", line 676, in get_job
    return Job.fetch(create_job_id(job_id), connection=get_redis_conn())
           ~~~~~~~~~^^^^^^^^^^^^^^^^^^^^^^^^^^^^^^^^^^^^^^^^^^^^^^^^^^^^
  File "/Users/mohammednishamnk/Documents/works/startecht/env/lib/python3.13/site-packages/rq/job.py", line 674, in fetch
    job.refresh()
    ~~~~~~~~~~~^^
  File "/Users/mohammednishamnk/Documents/works/startecht/env/lib/python3.13/site-packages/rq/job.py", line 1037, in refresh
    data = self.connection.hgetall(self.key)
  File "/Users/mohammednishamnk/Documents/works/startecht/env/lib/python3.13/site-packages/redis/commands/core.py", line 4959, in hgetall
    return self.execute_command("HGETALL", name, keys=[name])
           ~~~~~~~~~~~~~~~~~~~~^^^^^^^^^^^^^^^^^^^^^^^^^^^^^^
  File "/Users/mohammednishamnk/Documents/works/startecht/env/lib/python3.13/site-packages/redis/client.py", line 623, in execute_command
    return self._execute_command(*args, **options)
           ~~~~~~~~~~~~~~~~~~~~~^^^^^^^^^^^^^^^^^^
  File "/Users/mohammednishamnk/Documents/works/startecht/env/lib/python3.13/site-packages/redis/client.py", line 629, in _execute_command
    conn = self.connection or pool.get_connection()
                              ~~~~~~~~~~~~~~~~~~~^^
  File "/Users/mohammednishamnk/Documents/works/startecht/env/lib/python3.13/site-packages/redis/utils.py", line 191, in wrapper
    return func(*args, **kwargs)
  File "/Users/mohammednishamnk/Documents/works/startecht/env/lib/python3.13/site-packages/redis/connection.py", line 1530, in get_connection
    connection.connect()
    ~~~~~~~~~~~~~~~~~~^^
  File "/Users/mohammednishamnk/Documents/works/startecht/env/lib/python3.13/site-packages/redis/connection.py", line 379, in connect
    self.connect_check_health(check_health=True)
    ~~~~~~~~~~~~~~~~~~~~~~~~~^^^^^^^^^^^^^^^^^^^
  File "/Users/mohammednishamnk/Documents/works/startecht/env/lib/python3.13/site-packages/redis/connection.py", line 391, in connect_check_health
    raise ConnectionError(self._error_message(e))
redis.exceptions.ConnectionError: Error 61 connecting to 127.0.0.1:11000. Connection refused.
2025-10-02 06:31:33,584 ERROR scheduler Exception in Enqueue Events for Site erpnext.localhost
Traceback (most recent call last):
  File "/Users/mohammednishamnk/Documents/works/startecht/env/lib/python3.13/site-packages/redis/connection.py", line 385, in connect_check_health
    sock = self.retry.call_with_retry(
        lambda: self._connect(), lambda error: self.disconnect(error)
    )
  File "/Users/mohammednishamnk/Documents/works/startecht/env/lib/python3.13/site-packages/redis/retry.py", line 87, in call_with_retry
    return do()
  File "/Users/mohammednishamnk/Documents/works/startecht/env/lib/python3.13/site-packages/redis/connection.py", line 386, in <lambda>
    lambda: self._connect(), lambda error: self.disconnect(error)
            ~~~~~~~~~~~~~^^
  File "/Users/mohammednishamnk/Documents/works/startecht/env/lib/python3.13/site-packages/redis/connection.py", line 797, in _connect
    raise err
  File "/Users/mohammednishamnk/Documents/works/startecht/env/lib/python3.13/site-packages/redis/connection.py", line 781, in _connect
    sock.connect(socket_address)
    ~~~~~~~~~~~~^^^^^^^^^^^^^^^^
ConnectionRefusedError: [Errno 61] Connection refused

During handling of the above exception, another exception occurred:

Traceback (most recent call last):
  File "/Users/mohammednishamnk/Documents/works/startecht/apps/frappe/frappe/utils/scheduler.py", line 120, in enqueue_events_for_site
    enqueue_events()
    ~~~~~~~~~~~~~~^^
  File "/Users/mohammednishamnk/Documents/works/startecht/apps/frappe/frappe/utils/scheduler.py", line 140, in enqueue_events
    if job_type.enqueue():
       ~~~~~~~~~~~~~~~~^^
  File "/Users/mohammednishamnk/Documents/works/startecht/apps/frappe/frappe/core/doctype/scheduled_job_type/scheduled_job_type.py", line 74, in enqueue
    if not self.is_job_in_queue():
           ~~~~~~~~~~~~~~~~~~~~^^
  File "/Users/mohammednishamnk/Documents/works/startecht/apps/frappe/frappe/core/doctype/scheduled_job_type/scheduled_job_type.py", line 96, in is_job_in_queue
    return is_job_enqueued(self.rq_job_id)
  File "/Users/mohammednishamnk/Documents/works/startecht/apps/frappe/frappe/utils/background_jobs.py", line 665, in is_job_enqueued
    return get_job_status(job_id) in (JobStatus.QUEUED, JobStatus.STARTED)
           ~~~~~~~~~~~~~~^^^^^^^^
  File "/Users/mohammednishamnk/Documents/works/startecht/apps/frappe/frappe/utils/background_jobs.py", line 670, in get_job_status
    if job := get_job(job_id):
              ~~~~~~~^^^^^^^^
  File "/Users/mohammednishamnk/Documents/works/startecht/apps/frappe/frappe/utils/background_jobs.py", line 676, in get_job
    return Job.fetch(create_job_id(job_id), connection=get_redis_conn())
           ~~~~~~~~~^^^^^^^^^^^^^^^^^^^^^^^^^^^^^^^^^^^^^^^^^^^^^^^^^^^^
  File "/Users/mohammednishamnk/Documents/works/startecht/env/lib/python3.13/site-packages/rq/job.py", line 674, in fetch
    job.refresh()
    ~~~~~~~~~~~^^
  File "/Users/mohammednishamnk/Documents/works/startecht/env/lib/python3.13/site-packages/rq/job.py", line 1037, in refresh
    data = self.connection.hgetall(self.key)
  File "/Users/mohammednishamnk/Documents/works/startecht/env/lib/python3.13/site-packages/redis/commands/core.py", line 4959, in hgetall
    return self.execute_command("HGETALL", name, keys=[name])
           ~~~~~~~~~~~~~~~~~~~~^^^^^^^^^^^^^^^^^^^^^^^^^^^^^^
  File "/Users/mohammednishamnk/Documents/works/startecht/env/lib/python3.13/site-packages/redis/client.py", line 623, in execute_command
    return self._execute_command(*args, **options)
           ~~~~~~~~~~~~~~~~~~~~~^^^^^^^^^^^^^^^^^^
  File "/Users/mohammednishamnk/Documents/works/startecht/env/lib/python3.13/site-packages/redis/client.py", line 629, in _execute_command
    conn = self.connection or pool.get_connection()
                              ~~~~~~~~~~~~~~~~~~~^^
  File "/Users/mohammednishamnk/Documents/works/startecht/env/lib/python3.13/site-packages/redis/utils.py", line 191, in wrapper
    return func(*args, **kwargs)
  File "/Users/mohammednishamnk/Documents/works/startecht/env/lib/python3.13/site-packages/redis/connection.py", line 1530, in get_connection
    connection.connect()
    ~~~~~~~~~~~~~~~~~~^^
  File "/Users/mohammednishamnk/Documents/works/startecht/env/lib/python3.13/site-packages/redis/connection.py", line 379, in connect
    self.connect_check_health(check_health=True)
    ~~~~~~~~~~~~~~~~~~~~~~~~~^^^^^^^^^^^^^^^^^^^
  File "/Users/mohammednishamnk/Documents/works/startecht/env/lib/python3.13/site-packages/redis/connection.py", line 391, in connect_check_health
    raise ConnectionError(self._error_message(e))
redis.exceptions.ConnectionError: Error 61 connecting to 127.0.0.1:11000. Connection refused.
2025-10-02 06:34:00,926 ERROR scheduler Exception in Enqueue Events for Site erpnext.localhost
Traceback (most recent call last):
  File "/Users/mohammednishamnk/Documents/works/startecht/env/lib/python3.13/site-packages/redis/connection.py", line 385, in connect_check_health
    sock = self.retry.call_with_retry(
        lambda: self._connect(), lambda error: self.disconnect(error)
    )
  File "/Users/mohammednishamnk/Documents/works/startecht/env/lib/python3.13/site-packages/redis/retry.py", line 87, in call_with_retry
    return do()
  File "/Users/mohammednishamnk/Documents/works/startecht/env/lib/python3.13/site-packages/redis/connection.py", line 386, in <lambda>
    lambda: self._connect(), lambda error: self.disconnect(error)
            ~~~~~~~~~~~~~^^
  File "/Users/mohammednishamnk/Documents/works/startecht/env/lib/python3.13/site-packages/redis/connection.py", line 797, in _connect
    raise err
  File "/Users/mohammednishamnk/Documents/works/startecht/env/lib/python3.13/site-packages/redis/connection.py", line 781, in _connect
    sock.connect(socket_address)
    ~~~~~~~~~~~~^^^^^^^^^^^^^^^^
ConnectionRefusedError: [Errno 61] Connection refused

During handling of the above exception, another exception occurred:

Traceback (most recent call last):
  File "/Users/mohammednishamnk/Documents/works/startecht/apps/frappe/frappe/utils/scheduler.py", line 120, in enqueue_events_for_site
    enqueue_events()
    ~~~~~~~~~~~~~~^^
  File "/Users/mohammednishamnk/Documents/works/startecht/apps/frappe/frappe/utils/scheduler.py", line 140, in enqueue_events
    if job_type.enqueue():
       ~~~~~~~~~~~~~~~~^^
  File "/Users/mohammednishamnk/Documents/works/startecht/apps/frappe/frappe/core/doctype/scheduled_job_type/scheduled_job_type.py", line 74, in enqueue
    if not self.is_job_in_queue():
           ~~~~~~~~~~~~~~~~~~~~^^
  File "/Users/mohammednishamnk/Documents/works/startecht/apps/frappe/frappe/core/doctype/scheduled_job_type/scheduled_job_type.py", line 96, in is_job_in_queue
    return is_job_enqueued(self.rq_job_id)
  File "/Users/mohammednishamnk/Documents/works/startecht/apps/frappe/frappe/utils/background_jobs.py", line 665, in is_job_enqueued
    return get_job_status(job_id) in (JobStatus.QUEUED, JobStatus.STARTED)
           ~~~~~~~~~~~~~~^^^^^^^^
  File "/Users/mohammednishamnk/Documents/works/startecht/apps/frappe/frappe/utils/background_jobs.py", line 670, in get_job_status
    if job := get_job(job_id):
              ~~~~~~~^^^^^^^^
  File "/Users/mohammednishamnk/Documents/works/startecht/apps/frappe/frappe/utils/background_jobs.py", line 676, in get_job
    return Job.fetch(create_job_id(job_id), connection=get_redis_conn())
           ~~~~~~~~~^^^^^^^^^^^^^^^^^^^^^^^^^^^^^^^^^^^^^^^^^^^^^^^^^^^^
  File "/Users/mohammednishamnk/Documents/works/startecht/env/lib/python3.13/site-packages/rq/job.py", line 674, in fetch
    job.refresh()
    ~~~~~~~~~~~^^
  File "/Users/mohammednishamnk/Documents/works/startecht/env/lib/python3.13/site-packages/rq/job.py", line 1037, in refresh
    data = self.connection.hgetall(self.key)
  File "/Users/mohammednishamnk/Documents/works/startecht/env/lib/python3.13/site-packages/redis/commands/core.py", line 4959, in hgetall
    return self.execute_command("HGETALL", name, keys=[name])
           ~~~~~~~~~~~~~~~~~~~~^^^^^^^^^^^^^^^^^^^^^^^^^^^^^^
  File "/Users/mohammednishamnk/Documents/works/startecht/env/lib/python3.13/site-packages/redis/client.py", line 623, in execute_command
    return self._execute_command(*args, **options)
           ~~~~~~~~~~~~~~~~~~~~~^^^^^^^^^^^^^^^^^^
  File "/Users/mohammednishamnk/Documents/works/startecht/env/lib/python3.13/site-packages/redis/client.py", line 629, in _execute_command
    conn = self.connection or pool.get_connection()
                              ~~~~~~~~~~~~~~~~~~~^^
  File "/Users/mohammednishamnk/Documents/works/startecht/env/lib/python3.13/site-packages/redis/utils.py", line 191, in wrapper
    return func(*args, **kwargs)
  File "/Users/mohammednishamnk/Documents/works/startecht/env/lib/python3.13/site-packages/redis/connection.py", line 1530, in get_connection
    connection.connect()
    ~~~~~~~~~~~~~~~~~~^^
  File "/Users/mohammednishamnk/Documents/works/startecht/env/lib/python3.13/site-packages/redis/connection.py", line 379, in connect
    self.connect_check_health(check_health=True)
    ~~~~~~~~~~~~~~~~~~~~~~~~~^^^^^^^^^^^^^^^^^^^
  File "/Users/mohammednishamnk/Documents/works/startecht/env/lib/python3.13/site-packages/redis/connection.py", line 391, in connect_check_health
    raise ConnectionError(self._error_message(e))
redis.exceptions.ConnectionError: Error 61 connecting to 127.0.0.1:11000. Connection refused.
2025-10-02 06:38:01,083 ERROR scheduler Exception in Enqueue Events for Site erpnext.localhost
Traceback (most recent call last):
  File "/Users/mohammednishamnk/Documents/works/startecht/env/lib/python3.13/site-packages/redis/connection.py", line 385, in connect_check_health
    sock = self.retry.call_with_retry(
        lambda: self._connect(), lambda error: self.disconnect(error)
    )
  File "/Users/mohammednishamnk/Documents/works/startecht/env/lib/python3.13/site-packages/redis/retry.py", line 87, in call_with_retry
    return do()
  File "/Users/mohammednishamnk/Documents/works/startecht/env/lib/python3.13/site-packages/redis/connection.py", line 386, in <lambda>
    lambda: self._connect(), lambda error: self.disconnect(error)
            ~~~~~~~~~~~~~^^
  File "/Users/mohammednishamnk/Documents/works/startecht/env/lib/python3.13/site-packages/redis/connection.py", line 797, in _connect
    raise err
  File "/Users/mohammednishamnk/Documents/works/startecht/env/lib/python3.13/site-packages/redis/connection.py", line 781, in _connect
    sock.connect(socket_address)
    ~~~~~~~~~~~~^^^^^^^^^^^^^^^^
ConnectionRefusedError: [Errno 61] Connection refused

During handling of the above exception, another exception occurred:

Traceback (most recent call last):
  File "/Users/mohammednishamnk/Documents/works/startecht/apps/frappe/frappe/utils/scheduler.py", line 120, in enqueue_events_for_site
    enqueue_events()
    ~~~~~~~~~~~~~~^^
  File "/Users/mohammednishamnk/Documents/works/startecht/apps/frappe/frappe/utils/scheduler.py", line 140, in enqueue_events
    if job_type.enqueue():
       ~~~~~~~~~~~~~~~~^^
  File "/Users/mohammednishamnk/Documents/works/startecht/apps/frappe/frappe/core/doctype/scheduled_job_type/scheduled_job_type.py", line 74, in enqueue
    if not self.is_job_in_queue():
           ~~~~~~~~~~~~~~~~~~~~^^
  File "/Users/mohammednishamnk/Documents/works/startecht/apps/frappe/frappe/core/doctype/scheduled_job_type/scheduled_job_type.py", line 96, in is_job_in_queue
    return is_job_enqueued(self.rq_job_id)
  File "/Users/mohammednishamnk/Documents/works/startecht/apps/frappe/frappe/utils/background_jobs.py", line 665, in is_job_enqueued
    return get_job_status(job_id) in (JobStatus.QUEUED, JobStatus.STARTED)
           ~~~~~~~~~~~~~~^^^^^^^^
  File "/Users/mohammednishamnk/Documents/works/startecht/apps/frappe/frappe/utils/background_jobs.py", line 670, in get_job_status
    if job := get_job(job_id):
              ~~~~~~~^^^^^^^^
  File "/Users/mohammednishamnk/Documents/works/startecht/apps/frappe/frappe/utils/background_jobs.py", line 676, in get_job
    return Job.fetch(create_job_id(job_id), connection=get_redis_conn())
           ~~~~~~~~~^^^^^^^^^^^^^^^^^^^^^^^^^^^^^^^^^^^^^^^^^^^^^^^^^^^^
  File "/Users/mohammednishamnk/Documents/works/startecht/env/lib/python3.13/site-packages/rq/job.py", line 674, in fetch
    job.refresh()
    ~~~~~~~~~~~^^
  File "/Users/mohammednishamnk/Documents/works/startecht/env/lib/python3.13/site-packages/rq/job.py", line 1037, in refresh
    data = self.connection.hgetall(self.key)
  File "/Users/mohammednishamnk/Documents/works/startecht/env/lib/python3.13/site-packages/redis/commands/core.py", line 4959, in hgetall
    return self.execute_command("HGETALL", name, keys=[name])
           ~~~~~~~~~~~~~~~~~~~~^^^^^^^^^^^^^^^^^^^^^^^^^^^^^^
  File "/Users/mohammednishamnk/Documents/works/startecht/env/lib/python3.13/site-packages/redis/client.py", line 623, in execute_command
    return self._execute_command(*args, **options)
           ~~~~~~~~~~~~~~~~~~~~~^^^^^^^^^^^^^^^^^^
  File "/Users/mohammednishamnk/Documents/works/startecht/env/lib/python3.13/site-packages/redis/client.py", line 629, in _execute_command
    conn = self.connection or pool.get_connection()
                              ~~~~~~~~~~~~~~~~~~~^^
  File "/Users/mohammednishamnk/Documents/works/startecht/env/lib/python3.13/site-packages/redis/utils.py", line 191, in wrapper
    return func(*args, **kwargs)
  File "/Users/mohammednishamnk/Documents/works/startecht/env/lib/python3.13/site-packages/redis/connection.py", line 1530, in get_connection
    connection.connect()
    ~~~~~~~~~~~~~~~~~~^^
  File "/Users/mohammednishamnk/Documents/works/startecht/env/lib/python3.13/site-packages/redis/connection.py", line 379, in connect
    self.connect_check_health(check_health=True)
    ~~~~~~~~~~~~~~~~~~~~~~~~~^^^^^^^^^^^^^^^^^^^
  File "/Users/mohammednishamnk/Documents/works/startecht/env/lib/python3.13/site-packages/redis/connection.py", line 391, in connect_check_health
    raise ConnectionError(self._error_message(e))
redis.exceptions.ConnectionError: Error 61 connecting to 127.0.0.1:11000. Connection refused.
2025-10-02 06:42:00,370 ERROR scheduler Exception in Enqueue Events for Site erpnext.localhost
Traceback (most recent call last):
  File "/Users/mohammednishamnk/Documents/works/startecht/env/lib/python3.13/site-packages/redis/connection.py", line 385, in connect_check_health
    sock = self.retry.call_with_retry(
        lambda: self._connect(), lambda error: self.disconnect(error)
    )
  File "/Users/mohammednishamnk/Documents/works/startecht/env/lib/python3.13/site-packages/redis/retry.py", line 87, in call_with_retry
    return do()
  File "/Users/mohammednishamnk/Documents/works/startecht/env/lib/python3.13/site-packages/redis/connection.py", line 386, in <lambda>
    lambda: self._connect(), lambda error: self.disconnect(error)
            ~~~~~~~~~~~~~^^
  File "/Users/mohammednishamnk/Documents/works/startecht/env/lib/python3.13/site-packages/redis/connection.py", line 797, in _connect
    raise err
  File "/Users/mohammednishamnk/Documents/works/startecht/env/lib/python3.13/site-packages/redis/connection.py", line 781, in _connect
    sock.connect(socket_address)
    ~~~~~~~~~~~~^^^^^^^^^^^^^^^^
ConnectionRefusedError: [Errno 61] Connection refused

During handling of the above exception, another exception occurred:

Traceback (most recent call last):
  File "/Users/mohammednishamnk/Documents/works/startecht/apps/frappe/frappe/utils/scheduler.py", line 120, in enqueue_events_for_site
    enqueue_events()
    ~~~~~~~~~~~~~~^^
  File "/Users/mohammednishamnk/Documents/works/startecht/apps/frappe/frappe/utils/scheduler.py", line 140, in enqueue_events
    if job_type.enqueue():
       ~~~~~~~~~~~~~~~~^^
  File "/Users/mohammednishamnk/Documents/works/startecht/apps/frappe/frappe/core/doctype/scheduled_job_type/scheduled_job_type.py", line 74, in enqueue
    if not self.is_job_in_queue():
           ~~~~~~~~~~~~~~~~~~~~^^
  File "/Users/mohammednishamnk/Documents/works/startecht/apps/frappe/frappe/core/doctype/scheduled_job_type/scheduled_job_type.py", line 96, in is_job_in_queue
    return is_job_enqueued(self.rq_job_id)
  File "/Users/mohammednishamnk/Documents/works/startecht/apps/frappe/frappe/utils/background_jobs.py", line 665, in is_job_enqueued
    return get_job_status(job_id) in (JobStatus.QUEUED, JobStatus.STARTED)
           ~~~~~~~~~~~~~~^^^^^^^^
  File "/Users/mohammednishamnk/Documents/works/startecht/apps/frappe/frappe/utils/background_jobs.py", line 670, in get_job_status
    if job := get_job(job_id):
              ~~~~~~~^^^^^^^^
  File "/Users/mohammednishamnk/Documents/works/startecht/apps/frappe/frappe/utils/background_jobs.py", line 676, in get_job
    return Job.fetch(create_job_id(job_id), connection=get_redis_conn())
           ~~~~~~~~~^^^^^^^^^^^^^^^^^^^^^^^^^^^^^^^^^^^^^^^^^^^^^^^^^^^^
  File "/Users/mohammednishamnk/Documents/works/startecht/env/lib/python3.13/site-packages/rq/job.py", line 674, in fetch
    job.refresh()
    ~~~~~~~~~~~^^
  File "/Users/mohammednishamnk/Documents/works/startecht/env/lib/python3.13/site-packages/rq/job.py", line 1037, in refresh
    data = self.connection.hgetall(self.key)
  File "/Users/mohammednishamnk/Documents/works/startecht/env/lib/python3.13/site-packages/redis/commands/core.py", line 4959, in hgetall
    return self.execute_command("HGETALL", name, keys=[name])
           ~~~~~~~~~~~~~~~~~~~~^^^^^^^^^^^^^^^^^^^^^^^^^^^^^^
  File "/Users/mohammednishamnk/Documents/works/startecht/env/lib/python3.13/site-packages/redis/client.py", line 623, in execute_command
    return self._execute_command(*args, **options)
           ~~~~~~~~~~~~~~~~~~~~~^^^^^^^^^^^^^^^^^^
  File "/Users/mohammednishamnk/Documents/works/startecht/env/lib/python3.13/site-packages/redis/client.py", line 629, in _execute_command
    conn = self.connection or pool.get_connection()
                              ~~~~~~~~~~~~~~~~~~~^^
  File "/Users/mohammednishamnk/Documents/works/startecht/env/lib/python3.13/site-packages/redis/utils.py", line 191, in wrapper
    return func(*args, **kwargs)
  File "/Users/mohammednishamnk/Documents/works/startecht/env/lib/python3.13/site-packages/redis/connection.py", line 1530, in get_connection
    connection.connect()
    ~~~~~~~~~~~~~~~~~~^^
  File "/Users/mohammednishamnk/Documents/works/startecht/env/lib/python3.13/site-packages/redis/connection.py", line 379, in connect
    self.connect_check_health(check_health=True)
    ~~~~~~~~~~~~~~~~~~~~~~~~~^^^^^^^^^^^^^^^^^^^
  File "/Users/mohammednishamnk/Documents/works/startecht/env/lib/python3.13/site-packages/redis/connection.py", line 391, in connect_check_health
    raise ConnectionError(self._error_message(e))
redis.exceptions.ConnectionError: Error 61 connecting to 127.0.0.1:11000. Connection refused.
2025-10-02 06:46:00,793 ERROR scheduler Exception in Enqueue Events for Site erpnext.localhost
Traceback (most recent call last):
  File "/Users/mohammednishamnk/Documents/works/startecht/env/lib/python3.13/site-packages/redis/connection.py", line 385, in connect_check_health
    sock = self.retry.call_with_retry(
        lambda: self._connect(), lambda error: self.disconnect(error)
    )
  File "/Users/mohammednishamnk/Documents/works/startecht/env/lib/python3.13/site-packages/redis/retry.py", line 87, in call_with_retry
    return do()
  File "/Users/mohammednishamnk/Documents/works/startecht/env/lib/python3.13/site-packages/redis/connection.py", line 386, in <lambda>
    lambda: self._connect(), lambda error: self.disconnect(error)
            ~~~~~~~~~~~~~^^
  File "/Users/mohammednishamnk/Documents/works/startecht/env/lib/python3.13/site-packages/redis/connection.py", line 797, in _connect
    raise err
  File "/Users/mohammednishamnk/Documents/works/startecht/env/lib/python3.13/site-packages/redis/connection.py", line 781, in _connect
    sock.connect(socket_address)
    ~~~~~~~~~~~~^^^^^^^^^^^^^^^^
ConnectionRefusedError: [Errno 61] Connection refused

During handling of the above exception, another exception occurred:

Traceback (most recent call last):
  File "/Users/mohammednishamnk/Documents/works/startecht/apps/frappe/frappe/utils/scheduler.py", line 120, in enqueue_events_for_site
    enqueue_events()
    ~~~~~~~~~~~~~~^^
  File "/Users/mohammednishamnk/Documents/works/startecht/apps/frappe/frappe/utils/scheduler.py", line 140, in enqueue_events
    if job_type.enqueue():
       ~~~~~~~~~~~~~~~~^^
  File "/Users/mohammednishamnk/Documents/works/startecht/apps/frappe/frappe/core/doctype/scheduled_job_type/scheduled_job_type.py", line 74, in enqueue
    if not self.is_job_in_queue():
           ~~~~~~~~~~~~~~~~~~~~^^
  File "/Users/mohammednishamnk/Documents/works/startecht/apps/frappe/frappe/core/doctype/scheduled_job_type/scheduled_job_type.py", line 96, in is_job_in_queue
    return is_job_enqueued(self.rq_job_id)
  File "/Users/mohammednishamnk/Documents/works/startecht/apps/frappe/frappe/utils/background_jobs.py", line 665, in is_job_enqueued
    return get_job_status(job_id) in (JobStatus.QUEUED, JobStatus.STARTED)
           ~~~~~~~~~~~~~~^^^^^^^^
  File "/Users/mohammednishamnk/Documents/works/startecht/apps/frappe/frappe/utils/background_jobs.py", line 670, in get_job_status
    if job := get_job(job_id):
              ~~~~~~~^^^^^^^^
  File "/Users/mohammednishamnk/Documents/works/startecht/apps/frappe/frappe/utils/background_jobs.py", line 676, in get_job
    return Job.fetch(create_job_id(job_id), connection=get_redis_conn())
           ~~~~~~~~~^^^^^^^^^^^^^^^^^^^^^^^^^^^^^^^^^^^^^^^^^^^^^^^^^^^^
  File "/Users/mohammednishamnk/Documents/works/startecht/env/lib/python3.13/site-packages/rq/job.py", line 674, in fetch
    job.refresh()
    ~~~~~~~~~~~^^
  File "/Users/mohammednishamnk/Documents/works/startecht/env/lib/python3.13/site-packages/rq/job.py", line 1037, in refresh
    data = self.connection.hgetall(self.key)
  File "/Users/mohammednishamnk/Documents/works/startecht/env/lib/python3.13/site-packages/redis/commands/core.py", line 4959, in hgetall
    return self.execute_command("HGETALL", name, keys=[name])
           ~~~~~~~~~~~~~~~~~~~~^^^^^^^^^^^^^^^^^^^^^^^^^^^^^^
  File "/Users/mohammednishamnk/Documents/works/startecht/env/lib/python3.13/site-packages/redis/client.py", line 623, in execute_command
    return self._execute_command(*args, **options)
           ~~~~~~~~~~~~~~~~~~~~~^^^^^^^^^^^^^^^^^^
  File "/Users/mohammednishamnk/Documents/works/startecht/env/lib/python3.13/site-packages/redis/client.py", line 629, in _execute_command
    conn = self.connection or pool.get_connection()
                              ~~~~~~~~~~~~~~~~~~~^^
  File "/Users/mohammednishamnk/Documents/works/startecht/env/lib/python3.13/site-packages/redis/utils.py", line 191, in wrapper
    return func(*args, **kwargs)
  File "/Users/mohammednishamnk/Documents/works/startecht/env/lib/python3.13/site-packages/redis/connection.py", line 1530, in get_connection
    connection.connect()
    ~~~~~~~~~~~~~~~~~~^^
  File "/Users/mohammednishamnk/Documents/works/startecht/env/lib/python3.13/site-packages/redis/connection.py", line 379, in connect
    self.connect_check_health(check_health=True)
    ~~~~~~~~~~~~~~~~~~~~~~~~~^^^^^^^^^^^^^^^^^^^
  File "/Users/mohammednishamnk/Documents/works/startecht/env/lib/python3.13/site-packages/redis/connection.py", line 391, in connect_check_health
    raise ConnectionError(self._error_message(e))
redis.exceptions.ConnectionError: Error 61 connecting to 127.0.0.1:11000. Connection refused.
2025-10-02 06:50:00,974 ERROR scheduler Exception in Enqueue Events for Site erpnext.localhost
Traceback (most recent call last):
  File "/Users/mohammednishamnk/Documents/works/startecht/env/lib/python3.13/site-packages/redis/connection.py", line 385, in connect_check_health
    sock = self.retry.call_with_retry(
        lambda: self._connect(), lambda error: self.disconnect(error)
    )
  File "/Users/mohammednishamnk/Documents/works/startecht/env/lib/python3.13/site-packages/redis/retry.py", line 87, in call_with_retry
    return do()
  File "/Users/mohammednishamnk/Documents/works/startecht/env/lib/python3.13/site-packages/redis/connection.py", line 386, in <lambda>
    lambda: self._connect(), lambda error: self.disconnect(error)
            ~~~~~~~~~~~~~^^
  File "/Users/mohammednishamnk/Documents/works/startecht/env/lib/python3.13/site-packages/redis/connection.py", line 797, in _connect
    raise err
  File "/Users/mohammednishamnk/Documents/works/startecht/env/lib/python3.13/site-packages/redis/connection.py", line 781, in _connect
    sock.connect(socket_address)
    ~~~~~~~~~~~~^^^^^^^^^^^^^^^^
ConnectionRefusedError: [Errno 61] Connection refused

During handling of the above exception, another exception occurred:

Traceback (most recent call last):
  File "/Users/mohammednishamnk/Documents/works/startecht/apps/frappe/frappe/utils/scheduler.py", line 120, in enqueue_events_for_site
    enqueue_events()
    ~~~~~~~~~~~~~~^^
  File "/Users/mohammednishamnk/Documents/works/startecht/apps/frappe/frappe/utils/scheduler.py", line 140, in enqueue_events
    if job_type.enqueue():
       ~~~~~~~~~~~~~~~~^^
  File "/Users/mohammednishamnk/Documents/works/startecht/apps/frappe/frappe/core/doctype/scheduled_job_type/scheduled_job_type.py", line 74, in enqueue
    if not self.is_job_in_queue():
           ~~~~~~~~~~~~~~~~~~~~^^
  File "/Users/mohammednishamnk/Documents/works/startecht/apps/frappe/frappe/core/doctype/scheduled_job_type/scheduled_job_type.py", line 96, in is_job_in_queue
    return is_job_enqueued(self.rq_job_id)
  File "/Users/mohammednishamnk/Documents/works/startecht/apps/frappe/frappe/utils/background_jobs.py", line 665, in is_job_enqueued
    return get_job_status(job_id) in (JobStatus.QUEUED, JobStatus.STARTED)
           ~~~~~~~~~~~~~~^^^^^^^^
  File "/Users/mohammednishamnk/Documents/works/startecht/apps/frappe/frappe/utils/background_jobs.py", line 670, in get_job_status
    if job := get_job(job_id):
              ~~~~~~~^^^^^^^^
  File "/Users/mohammednishamnk/Documents/works/startecht/apps/frappe/frappe/utils/background_jobs.py", line 676, in get_job
    return Job.fetch(create_job_id(job_id), connection=get_redis_conn())
           ~~~~~~~~~^^^^^^^^^^^^^^^^^^^^^^^^^^^^^^^^^^^^^^^^^^^^^^^^^^^^
  File "/Users/mohammednishamnk/Documents/works/startecht/env/lib/python3.13/site-packages/rq/job.py", line 674, in fetch
    job.refresh()
    ~~~~~~~~~~~^^
  File "/Users/mohammednishamnk/Documents/works/startecht/env/lib/python3.13/site-packages/rq/job.py", line 1037, in refresh
    data = self.connection.hgetall(self.key)
  File "/Users/mohammednishamnk/Documents/works/startecht/env/lib/python3.13/site-packages/redis/commands/core.py", line 4959, in hgetall
    return self.execute_command("HGETALL", name, keys=[name])
           ~~~~~~~~~~~~~~~~~~~~^^^^^^^^^^^^^^^^^^^^^^^^^^^^^^
  File "/Users/mohammednishamnk/Documents/works/startecht/env/lib/python3.13/site-packages/redis/client.py", line 623, in execute_command
    return self._execute_command(*args, **options)
           ~~~~~~~~~~~~~~~~~~~~~^^^^^^^^^^^^^^^^^^
  File "/Users/mohammednishamnk/Documents/works/startecht/env/lib/python3.13/site-packages/redis/client.py", line 629, in _execute_command
    conn = self.connection or pool.get_connection()
                              ~~~~~~~~~~~~~~~~~~~^^
  File "/Users/mohammednishamnk/Documents/works/startecht/env/lib/python3.13/site-packages/redis/utils.py", line 191, in wrapper
    return func(*args, **kwargs)
  File "/Users/mohammednishamnk/Documents/works/startecht/env/lib/python3.13/site-packages/redis/connection.py", line 1530, in get_connection
    connection.connect()
    ~~~~~~~~~~~~~~~~~~^^
  File "/Users/mohammednishamnk/Documents/works/startecht/env/lib/python3.13/site-packages/redis/connection.py", line 379, in connect
    self.connect_check_health(check_health=True)
    ~~~~~~~~~~~~~~~~~~~~~~~~~^^^^^^^^^^^^^^^^^^^
  File "/Users/mohammednishamnk/Documents/works/startecht/env/lib/python3.13/site-packages/redis/connection.py", line 391, in connect_check_health
    raise ConnectionError(self._error_message(e))
redis.exceptions.ConnectionError: Error 61 connecting to 127.0.0.1:11000. Connection refused.
2025-10-02 06:54:00,225 ERROR scheduler Exception in Enqueue Events for Site erpnext.localhost
Traceback (most recent call last):
  File "/Users/mohammednishamnk/Documents/works/startecht/env/lib/python3.13/site-packages/redis/connection.py", line 385, in connect_check_health
    sock = self.retry.call_with_retry(
        lambda: self._connect(), lambda error: self.disconnect(error)
    )
  File "/Users/mohammednishamnk/Documents/works/startecht/env/lib/python3.13/site-packages/redis/retry.py", line 87, in call_with_retry
    return do()
  File "/Users/mohammednishamnk/Documents/works/startecht/env/lib/python3.13/site-packages/redis/connection.py", line 386, in <lambda>
    lambda: self._connect(), lambda error: self.disconnect(error)
            ~~~~~~~~~~~~~^^
  File "/Users/mohammednishamnk/Documents/works/startecht/env/lib/python3.13/site-packages/redis/connection.py", line 797, in _connect
    raise err
  File "/Users/mohammednishamnk/Documents/works/startecht/env/lib/python3.13/site-packages/redis/connection.py", line 781, in _connect
    sock.connect(socket_address)
    ~~~~~~~~~~~~^^^^^^^^^^^^^^^^
ConnectionRefusedError: [Errno 61] Connection refused

During handling of the above exception, another exception occurred:

Traceback (most recent call last):
  File "/Users/mohammednishamnk/Documents/works/startecht/apps/frappe/frappe/utils/scheduler.py", line 120, in enqueue_events_for_site
    enqueue_events()
    ~~~~~~~~~~~~~~^^
  File "/Users/mohammednishamnk/Documents/works/startecht/apps/frappe/frappe/utils/scheduler.py", line 140, in enqueue_events
    if job_type.enqueue():
       ~~~~~~~~~~~~~~~~^^
  File "/Users/mohammednishamnk/Documents/works/startecht/apps/frappe/frappe/core/doctype/scheduled_job_type/scheduled_job_type.py", line 74, in enqueue
    if not self.is_job_in_queue():
           ~~~~~~~~~~~~~~~~~~~~^^
  File "/Users/mohammednishamnk/Documents/works/startecht/apps/frappe/frappe/core/doctype/scheduled_job_type/scheduled_job_type.py", line 96, in is_job_in_queue
    return is_job_enqueued(self.rq_job_id)
  File "/Users/mohammednishamnk/Documents/works/startecht/apps/frappe/frappe/utils/background_jobs.py", line 665, in is_job_enqueued
    return get_job_status(job_id) in (JobStatus.QUEUED, JobStatus.STARTED)
           ~~~~~~~~~~~~~~^^^^^^^^
  File "/Users/mohammednishamnk/Documents/works/startecht/apps/frappe/frappe/utils/background_jobs.py", line 670, in get_job_status
    if job := get_job(job_id):
              ~~~~~~~^^^^^^^^
  File "/Users/mohammednishamnk/Documents/works/startecht/apps/frappe/frappe/utils/background_jobs.py", line 676, in get_job
    return Job.fetch(create_job_id(job_id), connection=get_redis_conn())
           ~~~~~~~~~^^^^^^^^^^^^^^^^^^^^^^^^^^^^^^^^^^^^^^^^^^^^^^^^^^^^
  File "/Users/mohammednishamnk/Documents/works/startecht/env/lib/python3.13/site-packages/rq/job.py", line 674, in fetch
    job.refresh()
    ~~~~~~~~~~~^^
  File "/Users/mohammednishamnk/Documents/works/startecht/env/lib/python3.13/site-packages/rq/job.py", line 1037, in refresh
    data = self.connection.hgetall(self.key)
  File "/Users/mohammednishamnk/Documents/works/startecht/env/lib/python3.13/site-packages/redis/commands/core.py", line 4959, in hgetall
    return self.execute_command("HGETALL", name, keys=[name])
           ~~~~~~~~~~~~~~~~~~~~^^^^^^^^^^^^^^^^^^^^^^^^^^^^^^
  File "/Users/mohammednishamnk/Documents/works/startecht/env/lib/python3.13/site-packages/redis/client.py", line 623, in execute_command
    return self._execute_command(*args, **options)
           ~~~~~~~~~~~~~~~~~~~~~^^^^^^^^^^^^^^^^^^
  File "/Users/mohammednishamnk/Documents/works/startecht/env/lib/python3.13/site-packages/redis/client.py", line 629, in _execute_command
    conn = self.connection or pool.get_connection()
                              ~~~~~~~~~~~~~~~~~~~^^
  File "/Users/mohammednishamnk/Documents/works/startecht/env/lib/python3.13/site-packages/redis/utils.py", line 191, in wrapper
    return func(*args, **kwargs)
  File "/Users/mohammednishamnk/Documents/works/startecht/env/lib/python3.13/site-packages/redis/connection.py", line 1530, in get_connection
    connection.connect()
    ~~~~~~~~~~~~~~~~~~^^
  File "/Users/mohammednishamnk/Documents/works/startecht/env/lib/python3.13/site-packages/redis/connection.py", line 379, in connect
    self.connect_check_health(check_health=True)
    ~~~~~~~~~~~~~~~~~~~~~~~~~^^^^^^^^^^^^^^^^^^^
  File "/Users/mohammednishamnk/Documents/works/startecht/env/lib/python3.13/site-packages/redis/connection.py", line 391, in connect_check_health
    raise ConnectionError(self._error_message(e))
redis.exceptions.ConnectionError: Error 61 connecting to 127.0.0.1:11000. Connection refused.
2025-10-02 06:58:00,538 ERROR scheduler Exception in Enqueue Events for Site erpnext.localhost
Traceback (most recent call last):
  File "/Users/mohammednishamnk/Documents/works/startecht/env/lib/python3.13/site-packages/redis/connection.py", line 385, in connect_check_health
    sock = self.retry.call_with_retry(
        lambda: self._connect(), lambda error: self.disconnect(error)
    )
  File "/Users/mohammednishamnk/Documents/works/startecht/env/lib/python3.13/site-packages/redis/retry.py", line 87, in call_with_retry
    return do()
  File "/Users/mohammednishamnk/Documents/works/startecht/env/lib/python3.13/site-packages/redis/connection.py", line 386, in <lambda>
    lambda: self._connect(), lambda error: self.disconnect(error)
            ~~~~~~~~~~~~~^^
  File "/Users/mohammednishamnk/Documents/works/startecht/env/lib/python3.13/site-packages/redis/connection.py", line 797, in _connect
    raise err
  File "/Users/mohammednishamnk/Documents/works/startecht/env/lib/python3.13/site-packages/redis/connection.py", line 781, in _connect
    sock.connect(socket_address)
    ~~~~~~~~~~~~^^^^^^^^^^^^^^^^
ConnectionRefusedError: [Errno 61] Connection refused

During handling of the above exception, another exception occurred:

Traceback (most recent call last):
  File "/Users/mohammednishamnk/Documents/works/startecht/apps/frappe/frappe/utils/scheduler.py", line 120, in enqueue_events_for_site
    enqueue_events()
    ~~~~~~~~~~~~~~^^
  File "/Users/mohammednishamnk/Documents/works/startecht/apps/frappe/frappe/utils/scheduler.py", line 140, in enqueue_events
    if job_type.enqueue():
       ~~~~~~~~~~~~~~~~^^
  File "/Users/mohammednishamnk/Documents/works/startecht/apps/frappe/frappe/core/doctype/scheduled_job_type/scheduled_job_type.py", line 74, in enqueue
    if not self.is_job_in_queue():
           ~~~~~~~~~~~~~~~~~~~~^^
  File "/Users/mohammednishamnk/Documents/works/startecht/apps/frappe/frappe/core/doctype/scheduled_job_type/scheduled_job_type.py", line 96, in is_job_in_queue
    return is_job_enqueued(self.rq_job_id)
  File "/Users/mohammednishamnk/Documents/works/startecht/apps/frappe/frappe/utils/background_jobs.py", line 665, in is_job_enqueued
    return get_job_status(job_id) in (JobStatus.QUEUED, JobStatus.STARTED)
           ~~~~~~~~~~~~~~^^^^^^^^
  File "/Users/mohammednishamnk/Documents/works/startecht/apps/frappe/frappe/utils/background_jobs.py", line 670, in get_job_status
    if job := get_job(job_id):
              ~~~~~~~^^^^^^^^
  File "/Users/mohammednishamnk/Documents/works/startecht/apps/frappe/frappe/utils/background_jobs.py", line 676, in get_job
    return Job.fetch(create_job_id(job_id), connection=get_redis_conn())
           ~~~~~~~~~^^^^^^^^^^^^^^^^^^^^^^^^^^^^^^^^^^^^^^^^^^^^^^^^^^^^
  File "/Users/mohammednishamnk/Documents/works/startecht/env/lib/python3.13/site-packages/rq/job.py", line 674, in fetch
    job.refresh()
    ~~~~~~~~~~~^^
  File "/Users/mohammednishamnk/Documents/works/startecht/env/lib/python3.13/site-packages/rq/job.py", line 1037, in refresh
    data = self.connection.hgetall(self.key)
  File "/Users/mohammednishamnk/Documents/works/startecht/env/lib/python3.13/site-packages/redis/commands/core.py", line 4959, in hgetall
    return self.execute_command("HGETALL", name, keys=[name])
           ~~~~~~~~~~~~~~~~~~~~^^^^^^^^^^^^^^^^^^^^^^^^^^^^^^
  File "/Users/mohammednishamnk/Documents/works/startecht/env/lib/python3.13/site-packages/redis/client.py", line 623, in execute_command
    return self._execute_command(*args, **options)
           ~~~~~~~~~~~~~~~~~~~~~^^^^^^^^^^^^^^^^^^
  File "/Users/mohammednishamnk/Documents/works/startecht/env/lib/python3.13/site-packages/redis/client.py", line 629, in _execute_command
    conn = self.connection or pool.get_connection()
                              ~~~~~~~~~~~~~~~~~~~^^
  File "/Users/mohammednishamnk/Documents/works/startecht/env/lib/python3.13/site-packages/redis/utils.py", line 191, in wrapper
    return func(*args, **kwargs)
  File "/Users/mohammednishamnk/Documents/works/startecht/env/lib/python3.13/site-packages/redis/connection.py", line 1530, in get_connection
    connection.connect()
    ~~~~~~~~~~~~~~~~~~^^
  File "/Users/mohammednishamnk/Documents/works/startecht/env/lib/python3.13/site-packages/redis/connection.py", line 379, in connect
    self.connect_check_health(check_health=True)
    ~~~~~~~~~~~~~~~~~~~~~~~~~^^^^^^^^^^^^^^^^^^^
  File "/Users/mohammednishamnk/Documents/works/startecht/env/lib/python3.13/site-packages/redis/connection.py", line 391, in connect_check_health
    raise ConnectionError(self._error_message(e))
redis.exceptions.ConnectionError: Error 61 connecting to 127.0.0.1:11000. Connection refused.
2025-10-02 07:02:00,779 ERROR scheduler Exception in Enqueue Events for Site erpnext.localhost
Traceback (most recent call last):
  File "/Users/mohammednishamnk/Documents/works/startecht/env/lib/python3.13/site-packages/redis/connection.py", line 385, in connect_check_health
    sock = self.retry.call_with_retry(
        lambda: self._connect(), lambda error: self.disconnect(error)
    )
  File "/Users/mohammednishamnk/Documents/works/startecht/env/lib/python3.13/site-packages/redis/retry.py", line 87, in call_with_retry
    return do()
  File "/Users/mohammednishamnk/Documents/works/startecht/env/lib/python3.13/site-packages/redis/connection.py", line 386, in <lambda>
    lambda: self._connect(), lambda error: self.disconnect(error)
            ~~~~~~~~~~~~~^^
  File "/Users/mohammednishamnk/Documents/works/startecht/env/lib/python3.13/site-packages/redis/connection.py", line 797, in _connect
    raise err
  File "/Users/mohammednishamnk/Documents/works/startecht/env/lib/python3.13/site-packages/redis/connection.py", line 781, in _connect
    sock.connect(socket_address)
    ~~~~~~~~~~~~^^^^^^^^^^^^^^^^
ConnectionRefusedError: [Errno 61] Connection refused

During handling of the above exception, another exception occurred:

Traceback (most recent call last):
  File "/Users/mohammednishamnk/Documents/works/startecht/apps/frappe/frappe/utils/scheduler.py", line 120, in enqueue_events_for_site
    enqueue_events()
    ~~~~~~~~~~~~~~^^
  File "/Users/mohammednishamnk/Documents/works/startecht/apps/frappe/frappe/utils/scheduler.py", line 140, in enqueue_events
    if job_type.enqueue():
       ~~~~~~~~~~~~~~~~^^
  File "/Users/mohammednishamnk/Documents/works/startecht/apps/frappe/frappe/core/doctype/scheduled_job_type/scheduled_job_type.py", line 74, in enqueue
    if not self.is_job_in_queue():
           ~~~~~~~~~~~~~~~~~~~~^^
  File "/Users/mohammednishamnk/Documents/works/startecht/apps/frappe/frappe/core/doctype/scheduled_job_type/scheduled_job_type.py", line 96, in is_job_in_queue
    return is_job_enqueued(self.rq_job_id)
  File "/Users/mohammednishamnk/Documents/works/startecht/apps/frappe/frappe/utils/background_jobs.py", line 665, in is_job_enqueued
    return get_job_status(job_id) in (JobStatus.QUEUED, JobStatus.STARTED)
           ~~~~~~~~~~~~~~^^^^^^^^
  File "/Users/mohammednishamnk/Documents/works/startecht/apps/frappe/frappe/utils/background_jobs.py", line 670, in get_job_status
    if job := get_job(job_id):
              ~~~~~~~^^^^^^^^
  File "/Users/mohammednishamnk/Documents/works/startecht/apps/frappe/frappe/utils/background_jobs.py", line 676, in get_job
    return Job.fetch(create_job_id(job_id), connection=get_redis_conn())
           ~~~~~~~~~^^^^^^^^^^^^^^^^^^^^^^^^^^^^^^^^^^^^^^^^^^^^^^^^^^^^
  File "/Users/mohammednishamnk/Documents/works/startecht/env/lib/python3.13/site-packages/rq/job.py", line 674, in fetch
    job.refresh()
    ~~~~~~~~~~~^^
  File "/Users/mohammednishamnk/Documents/works/startecht/env/lib/python3.13/site-packages/rq/job.py", line 1037, in refresh
    data = self.connection.hgetall(self.key)
  File "/Users/mohammednishamnk/Documents/works/startecht/env/lib/python3.13/site-packages/redis/commands/core.py", line 4959, in hgetall
    return self.execute_command("HGETALL", name, keys=[name])
           ~~~~~~~~~~~~~~~~~~~~^^^^^^^^^^^^^^^^^^^^^^^^^^^^^^
  File "/Users/mohammednishamnk/Documents/works/startecht/env/lib/python3.13/site-packages/redis/client.py", line 623, in execute_command
    return self._execute_command(*args, **options)
           ~~~~~~~~~~~~~~~~~~~~~^^^^^^^^^^^^^^^^^^
  File "/Users/mohammednishamnk/Documents/works/startecht/env/lib/python3.13/site-packages/redis/client.py", line 629, in _execute_command
    conn = self.connection or pool.get_connection()
                              ~~~~~~~~~~~~~~~~~~~^^
  File "/Users/mohammednishamnk/Documents/works/startecht/env/lib/python3.13/site-packages/redis/utils.py", line 191, in wrapper
    return func(*args, **kwargs)
  File "/Users/mohammednishamnk/Documents/works/startecht/env/lib/python3.13/site-packages/redis/connection.py", line 1530, in get_connection
    connection.connect()
    ~~~~~~~~~~~~~~~~~~^^
  File "/Users/mohammednishamnk/Documents/works/startecht/env/lib/python3.13/site-packages/redis/connection.py", line 379, in connect
    self.connect_check_health(check_health=True)
    ~~~~~~~~~~~~~~~~~~~~~~~~~^^^^^^^^^^^^^^^^^^^
  File "/Users/mohammednishamnk/Documents/works/startecht/env/lib/python3.13/site-packages/redis/connection.py", line 391, in connect_check_health
    raise ConnectionError(self._error_message(e))
redis.exceptions.ConnectionError: Error 61 connecting to 127.0.0.1:11000. Connection refused.
2025-10-02 07:06:01,060 ERROR scheduler Exception in Enqueue Events for Site erpnext.localhost
Traceback (most recent call last):
  File "/Users/mohammednishamnk/Documents/works/startecht/env/lib/python3.13/site-packages/redis/connection.py", line 385, in connect_check_health
    sock = self.retry.call_with_retry(
        lambda: self._connect(), lambda error: self.disconnect(error)
    )
  File "/Users/mohammednishamnk/Documents/works/startecht/env/lib/python3.13/site-packages/redis/retry.py", line 87, in call_with_retry
    return do()
  File "/Users/mohammednishamnk/Documents/works/startecht/env/lib/python3.13/site-packages/redis/connection.py", line 386, in <lambda>
    lambda: self._connect(), lambda error: self.disconnect(error)
            ~~~~~~~~~~~~~^^
  File "/Users/mohammednishamnk/Documents/works/startecht/env/lib/python3.13/site-packages/redis/connection.py", line 797, in _connect
    raise err
  File "/Users/mohammednishamnk/Documents/works/startecht/env/lib/python3.13/site-packages/redis/connection.py", line 781, in _connect
    sock.connect(socket_address)
    ~~~~~~~~~~~~^^^^^^^^^^^^^^^^
ConnectionRefusedError: [Errno 61] Connection refused

During handling of the above exception, another exception occurred:

Traceback (most recent call last):
  File "/Users/mohammednishamnk/Documents/works/startecht/apps/frappe/frappe/utils/scheduler.py", line 120, in enqueue_events_for_site
    enqueue_events()
    ~~~~~~~~~~~~~~^^
  File "/Users/mohammednishamnk/Documents/works/startecht/apps/frappe/frappe/utils/scheduler.py", line 140, in enqueue_events
    if job_type.enqueue():
       ~~~~~~~~~~~~~~~~^^
  File "/Users/mohammednishamnk/Documents/works/startecht/apps/frappe/frappe/core/doctype/scheduled_job_type/scheduled_job_type.py", line 74, in enqueue
    if not self.is_job_in_queue():
           ~~~~~~~~~~~~~~~~~~~~^^
  File "/Users/mohammednishamnk/Documents/works/startecht/apps/frappe/frappe/core/doctype/scheduled_job_type/scheduled_job_type.py", line 96, in is_job_in_queue
    return is_job_enqueued(self.rq_job_id)
  File "/Users/mohammednishamnk/Documents/works/startecht/apps/frappe/frappe/utils/background_jobs.py", line 665, in is_job_enqueued
    return get_job_status(job_id) in (JobStatus.QUEUED, JobStatus.STARTED)
           ~~~~~~~~~~~~~~^^^^^^^^
  File "/Users/mohammednishamnk/Documents/works/startecht/apps/frappe/frappe/utils/background_jobs.py", line 670, in get_job_status
    if job := get_job(job_id):
              ~~~~~~~^^^^^^^^
  File "/Users/mohammednishamnk/Documents/works/startecht/apps/frappe/frappe/utils/background_jobs.py", line 676, in get_job
    return Job.fetch(create_job_id(job_id), connection=get_redis_conn())
           ~~~~~~~~~^^^^^^^^^^^^^^^^^^^^^^^^^^^^^^^^^^^^^^^^^^^^^^^^^^^^
  File "/Users/mohammednishamnk/Documents/works/startecht/env/lib/python3.13/site-packages/rq/job.py", line 674, in fetch
    job.refresh()
    ~~~~~~~~~~~^^
  File "/Users/mohammednishamnk/Documents/works/startecht/env/lib/python3.13/site-packages/rq/job.py", line 1037, in refresh
    data = self.connection.hgetall(self.key)
  File "/Users/mohammednishamnk/Documents/works/startecht/env/lib/python3.13/site-packages/redis/commands/core.py", line 4959, in hgetall
    return self.execute_command("HGETALL", name, keys=[name])
           ~~~~~~~~~~~~~~~~~~~~^^^^^^^^^^^^^^^^^^^^^^^^^^^^^^
  File "/Users/mohammednishamnk/Documents/works/startecht/env/lib/python3.13/site-packages/redis/client.py", line 623, in execute_command
    return self._execute_command(*args, **options)
           ~~~~~~~~~~~~~~~~~~~~~^^^^^^^^^^^^^^^^^^
  File "/Users/mohammednishamnk/Documents/works/startecht/env/lib/python3.13/site-packages/redis/client.py", line 629, in _execute_command
    conn = self.connection or pool.get_connection()
                              ~~~~~~~~~~~~~~~~~~~^^
  File "/Users/mohammednishamnk/Documents/works/startecht/env/lib/python3.13/site-packages/redis/utils.py", line 191, in wrapper
    return func(*args, **kwargs)
  File "/Users/mohammednishamnk/Documents/works/startecht/env/lib/python3.13/site-packages/redis/connection.py", line 1530, in get_connection
    connection.connect()
    ~~~~~~~~~~~~~~~~~~^^
  File "/Users/mohammednishamnk/Documents/works/startecht/env/lib/python3.13/site-packages/redis/connection.py", line 379, in connect
    self.connect_check_health(check_health=True)
    ~~~~~~~~~~~~~~~~~~~~~~~~~^^^^^^^^^^^^^^^^^^^
  File "/Users/mohammednishamnk/Documents/works/startecht/env/lib/python3.13/site-packages/redis/connection.py", line 391, in connect_check_health
    raise ConnectionError(self._error_message(e))
redis.exceptions.ConnectionError: Error 61 connecting to 127.0.0.1:11000. Connection refused.
2025-10-02 07:10:00,229 ERROR scheduler Exception in Enqueue Events for Site erpnext.localhost
Traceback (most recent call last):
  File "/Users/mohammednishamnk/Documents/works/startecht/env/lib/python3.13/site-packages/redis/connection.py", line 385, in connect_check_health
    sock = self.retry.call_with_retry(
        lambda: self._connect(), lambda error: self.disconnect(error)
    )
  File "/Users/mohammednishamnk/Documents/works/startecht/env/lib/python3.13/site-packages/redis/retry.py", line 87, in call_with_retry
    return do()
  File "/Users/mohammednishamnk/Documents/works/startecht/env/lib/python3.13/site-packages/redis/connection.py", line 386, in <lambda>
    lambda: self._connect(), lambda error: self.disconnect(error)
            ~~~~~~~~~~~~~^^
  File "/Users/mohammednishamnk/Documents/works/startecht/env/lib/python3.13/site-packages/redis/connection.py", line 797, in _connect
    raise err
  File "/Users/mohammednishamnk/Documents/works/startecht/env/lib/python3.13/site-packages/redis/connection.py", line 781, in _connect
    sock.connect(socket_address)
    ~~~~~~~~~~~~^^^^^^^^^^^^^^^^
ConnectionRefusedError: [Errno 61] Connection refused

During handling of the above exception, another exception occurred:

Traceback (most recent call last):
  File "/Users/mohammednishamnk/Documents/works/startecht/apps/frappe/frappe/utils/scheduler.py", line 120, in enqueue_events_for_site
    enqueue_events()
    ~~~~~~~~~~~~~~^^
  File "/Users/mohammednishamnk/Documents/works/startecht/apps/frappe/frappe/utils/scheduler.py", line 140, in enqueue_events
    if job_type.enqueue():
       ~~~~~~~~~~~~~~~~^^
  File "/Users/mohammednishamnk/Documents/works/startecht/apps/frappe/frappe/core/doctype/scheduled_job_type/scheduled_job_type.py", line 74, in enqueue
    if not self.is_job_in_queue():
           ~~~~~~~~~~~~~~~~~~~~^^
  File "/Users/mohammednishamnk/Documents/works/startecht/apps/frappe/frappe/core/doctype/scheduled_job_type/scheduled_job_type.py", line 96, in is_job_in_queue
    return is_job_enqueued(self.rq_job_id)
  File "/Users/mohammednishamnk/Documents/works/startecht/apps/frappe/frappe/utils/background_jobs.py", line 665, in is_job_enqueued
    return get_job_status(job_id) in (JobStatus.QUEUED, JobStatus.STARTED)
           ~~~~~~~~~~~~~~^^^^^^^^
  File "/Users/mohammednishamnk/Documents/works/startecht/apps/frappe/frappe/utils/background_jobs.py", line 670, in get_job_status
    if job := get_job(job_id):
              ~~~~~~~^^^^^^^^
  File "/Users/mohammednishamnk/Documents/works/startecht/apps/frappe/frappe/utils/background_jobs.py", line 676, in get_job
    return Job.fetch(create_job_id(job_id), connection=get_redis_conn())
           ~~~~~~~~~^^^^^^^^^^^^^^^^^^^^^^^^^^^^^^^^^^^^^^^^^^^^^^^^^^^^
  File "/Users/mohammednishamnk/Documents/works/startecht/env/lib/python3.13/site-packages/rq/job.py", line 674, in fetch
    job.refresh()
    ~~~~~~~~~~~^^
  File "/Users/mohammednishamnk/Documents/works/startecht/env/lib/python3.13/site-packages/rq/job.py", line 1037, in refresh
    data = self.connection.hgetall(self.key)
  File "/Users/mohammednishamnk/Documents/works/startecht/env/lib/python3.13/site-packages/redis/commands/core.py", line 4959, in hgetall
    return self.execute_command("HGETALL", name, keys=[name])
           ~~~~~~~~~~~~~~~~~~~~^^^^^^^^^^^^^^^^^^^^^^^^^^^^^^
  File "/Users/mohammednishamnk/Documents/works/startecht/env/lib/python3.13/site-packages/redis/client.py", line 623, in execute_command
    return self._execute_command(*args, **options)
           ~~~~~~~~~~~~~~~~~~~~~^^^^^^^^^^^^^^^^^^
  File "/Users/mohammednishamnk/Documents/works/startecht/env/lib/python3.13/site-packages/redis/client.py", line 629, in _execute_command
    conn = self.connection or pool.get_connection()
                              ~~~~~~~~~~~~~~~~~~~^^
  File "/Users/mohammednishamnk/Documents/works/startecht/env/lib/python3.13/site-packages/redis/utils.py", line 191, in wrapper
    return func(*args, **kwargs)
  File "/Users/mohammednishamnk/Documents/works/startecht/env/lib/python3.13/site-packages/redis/connection.py", line 1530, in get_connection
    connection.connect()
    ~~~~~~~~~~~~~~~~~~^^
  File "/Users/mohammednishamnk/Documents/works/startecht/env/lib/python3.13/site-packages/redis/connection.py", line 379, in connect
    self.connect_check_health(check_health=True)
    ~~~~~~~~~~~~~~~~~~~~~~~~~^^^^^^^^^^^^^^^^^^^
  File "/Users/mohammednishamnk/Documents/works/startecht/env/lib/python3.13/site-packages/redis/connection.py", line 391, in connect_check_health
    raise ConnectionError(self._error_message(e))
redis.exceptions.ConnectionError: Error 61 connecting to 127.0.0.1:11000. Connection refused.
2025-10-02 09:26:42,797 ERROR scheduler Exception in Enqueue Events for Site erpnext.localhost
Traceback (most recent call last):
  File "/Users/mohammednishamnk/Documents/works/startecht/env/lib/python3.13/site-packages/redis/connection.py", line 385, in connect_check_health
    sock = self.retry.call_with_retry(
        lambda: self._connect(), lambda error: self.disconnect(error)
    )
  File "/Users/mohammednishamnk/Documents/works/startecht/env/lib/python3.13/site-packages/redis/retry.py", line 87, in call_with_retry
    return do()
  File "/Users/mohammednishamnk/Documents/works/startecht/env/lib/python3.13/site-packages/redis/connection.py", line 386, in <lambda>
    lambda: self._connect(), lambda error: self.disconnect(error)
            ~~~~~~~~~~~~~^^
  File "/Users/mohammednishamnk/Documents/works/startecht/env/lib/python3.13/site-packages/redis/connection.py", line 797, in _connect
    raise err
  File "/Users/mohammednishamnk/Documents/works/startecht/env/lib/python3.13/site-packages/redis/connection.py", line 781, in _connect
    sock.connect(socket_address)
    ~~~~~~~~~~~~^^^^^^^^^^^^^^^^
ConnectionRefusedError: [Errno 61] Connection refused

During handling of the above exception, another exception occurred:

Traceback (most recent call last):
  File "/Users/mohammednishamnk/Documents/works/startecht/apps/frappe/frappe/utils/scheduler.py", line 120, in enqueue_events_for_site
    enqueue_events()
    ~~~~~~~~~~~~~~^^
  File "/Users/mohammednishamnk/Documents/works/startecht/apps/frappe/frappe/utils/scheduler.py", line 140, in enqueue_events
    if job_type.enqueue():
       ~~~~~~~~~~~~~~~~^^
  File "/Users/mohammednishamnk/Documents/works/startecht/apps/frappe/frappe/core/doctype/scheduled_job_type/scheduled_job_type.py", line 74, in enqueue
    if not self.is_job_in_queue():
           ~~~~~~~~~~~~~~~~~~~~^^
  File "/Users/mohammednishamnk/Documents/works/startecht/apps/frappe/frappe/core/doctype/scheduled_job_type/scheduled_job_type.py", line 96, in is_job_in_queue
    return is_job_enqueued(self.rq_job_id)
  File "/Users/mohammednishamnk/Documents/works/startecht/apps/frappe/frappe/utils/background_jobs.py", line 665, in is_job_enqueued
    return get_job_status(job_id) in (JobStatus.QUEUED, JobStatus.STARTED)
           ~~~~~~~~~~~~~~^^^^^^^^
  File "/Users/mohammednishamnk/Documents/works/startecht/apps/frappe/frappe/utils/background_jobs.py", line 670, in get_job_status
    if job := get_job(job_id):
              ~~~~~~~^^^^^^^^
  File "/Users/mohammednishamnk/Documents/works/startecht/apps/frappe/frappe/utils/background_jobs.py", line 676, in get_job
    return Job.fetch(create_job_id(job_id), connection=get_redis_conn())
           ~~~~~~~~~^^^^^^^^^^^^^^^^^^^^^^^^^^^^^^^^^^^^^^^^^^^^^^^^^^^^
  File "/Users/mohammednishamnk/Documents/works/startecht/env/lib/python3.13/site-packages/rq/job.py", line 674, in fetch
    job.refresh()
    ~~~~~~~~~~~^^
  File "/Users/mohammednishamnk/Documents/works/startecht/env/lib/python3.13/site-packages/rq/job.py", line 1037, in refresh
    data = self.connection.hgetall(self.key)
  File "/Users/mohammednishamnk/Documents/works/startecht/env/lib/python3.13/site-packages/redis/commands/core.py", line 4959, in hgetall
    return self.execute_command("HGETALL", name, keys=[name])
           ~~~~~~~~~~~~~~~~~~~~^^^^^^^^^^^^^^^^^^^^^^^^^^^^^^
  File "/Users/mohammednishamnk/Documents/works/startecht/env/lib/python3.13/site-packages/redis/client.py", line 623, in execute_command
    return self._execute_command(*args, **options)
           ~~~~~~~~~~~~~~~~~~~~~^^^^^^^^^^^^^^^^^^
  File "/Users/mohammednishamnk/Documents/works/startecht/env/lib/python3.13/site-packages/redis/client.py", line 629, in _execute_command
    conn = self.connection or pool.get_connection()
                              ~~~~~~~~~~~~~~~~~~~^^
  File "/Users/mohammednishamnk/Documents/works/startecht/env/lib/python3.13/site-packages/redis/utils.py", line 191, in wrapper
    return func(*args, **kwargs)
  File "/Users/mohammednishamnk/Documents/works/startecht/env/lib/python3.13/site-packages/redis/connection.py", line 1530, in get_connection
    connection.connect()
    ~~~~~~~~~~~~~~~~~~^^
  File "/Users/mohammednishamnk/Documents/works/startecht/env/lib/python3.13/site-packages/redis/connection.py", line 379, in connect
    self.connect_check_health(check_health=True)
    ~~~~~~~~~~~~~~~~~~~~~~~~~^^^^^^^^^^^^^^^^^^^
  File "/Users/mohammednishamnk/Documents/works/startecht/env/lib/python3.13/site-packages/redis/connection.py", line 391, in connect_check_health
    raise ConnectionError(self._error_message(e))
redis.exceptions.ConnectionError: Error 61 connecting to 127.0.0.1:11000. Connection refused.
